Workbook

Sheet 按到港分类货柜清单
A1: 分类 | B1: 集装箱号 | D1: 物流状态 | E1: EXCEL | G1: 目的港 | H1: ETA（预计到港） | I1: ATA（实际到港） | J1: 备货单号 | K1: 出运日期 | L1: 还箱日期
A2: 今日之前到港未提柜 | B2: BEAU5730626 | D2: at_port | E2: =VLOOKUP(J2,Sheet1!C:H,5,0) -> 未清关 | G2: 纽瓦克 | H2: 2026-02-18 | I2: 2026-02-18 | J2: 25DSA5613
A3: 今日之前到港未提柜 | B3: CAAU9221491 | D3: at_port | E3: =VLOOKUP(J3,Sheet1!C:H,5,0) -> 未清关 | G3: 萨凡纳 | H3: 2026-02-25 | I3: 2026-02-25 | J3: 25DSA5987
A4: 今日之前到港未提柜 | B4: CAIU7235539 | D4: at_port | E4: =VLOOKUP(J4,Sheet1!C:H,5,0) -> 未清关 | G4: 洛杉矶 | H4: 2026-02-19 | I4: 2026-02-19 | J4: 25DSA06516
A5: 今日之前到港未提柜 | B5: CAIU9970363 | D5: at_port | E5: =VLOOKUP(J5,Sheet1!C:H,5,0) -> 未清关 | G5: 萨凡纳 | H5: 2026-02-25 | I5: 2026-02-24 | J5: 25DSA06334
A6: 今日之前到港未提柜 | B6: FSCU8507808 | D6: at_port | E6: =VLOOKUP(J6,Sheet1!C:H,5,0) -> 未清关 | G6: 萨凡纳 | H6: 2026-02-25 | I6: 2026-02-24 | J6: 25DSA06328
A7: 今日之前到港未提柜 | B7: GCXU5599790 | D7: at_port | E7: =VLOOKUP(J7,Sheet1!C:H,5,0) -> 未清关 | G7: 洛杉矶 | H7: 2026-02-25 | I7: 2026-02-25 | J7: 25DSA6072
A8: 今日之前到港未提柜 | B8: HASU4405826 | D8: at_port | E8: =VLOOKUP(J8,Sheet1!C:H,5,0) -> 未清关 | G8: 洛杉矶 | H8: 2026-02-25 | I8: 2026-02-25 | J8: 25DSA6073
A9: 今日之前到港未提柜 | B9: HMMU4016860 | D9: at_port | E9: =VLOOKUP(J9,Sheet1!C:H,5,0) -> 未清关 | G9: 萨凡纳 | H9: 2026-02-25 | I9: 2026-02-24 | J9: 25DSA06317
A10: 今日之前到港未提柜 | B10: HMMU4139490 | D10: at_port | E10: =VLOOKUP(J10,Sheet1!C:H,5,0) -> 未清关 | G10: 萨凡纳 | H10: 2026-02-25 | I10: 2026-02-24 | J10: 25DSA06319
A11: 今日之前到港未提柜 | B11: HMMU4181756 | D11: at_port | E11: =VLOOKUP(J11,Sheet1!C:H,5,0) -> 未清关 | G11: 长滩 | H11: 2026-02-22 | I11: 2026-02-23 | J11: 25DSA06290
A12: 今日之前到港未提柜 | B12: HMMU4753337 | D12: at_port | E12: =VLOOKUP(J12,Sheet1!C:H,5,0) -> 未清关 | G12: 长滩 | H12: 2026-02-22 | I12: 2026-02-23 | J12: 25DSA06273
A13: 今日之前到港未提柜 | B13: HMMU6350686 | D13: at_port | E13: =VLOOKUP(J13,Sheet1!C:H,5,0) -> 未清关 | G13: 萨凡纳 | H13: 2026-02-25 | I13: 2026-02-24 | J13: 25DSA06331
... A47: 今日之前到港未提柜 | B47: UETU7804928 | D47: at_port | E47: =VLOOKUP(J47,Sheet1!C:H,5,0) -> 未清关 | G47: 萨凡纳 | H47: 2026-02-24 | I47: 2026-02-24 | J47: 25DSA06311
A48: 今日之前到港已提柜 | B48: BEAU5745293 | C48: =_xlfn.XLOOKUP($B48,Sheet1!$I:$I,Sheet1!AS:AS,0,0,1) -> 2026-02-05 00:00:00 | D48: returned_empty | E48: =VLOOKUP(J48,Sheet1!C:H,5,0) -> 已完成 | G48: 洛杉矶 | H48: 2026-02-04 | I48: 2026-02-03 | J48: 25DSA5841 | L48: =_xlfn.XLOOKUP($B48,Sheet1!$I:$I,Sheet1!BB:BB,0,0,1) -> 2026-02-11 13:41:00
A49: 今日之前到港已提柜 | B49: BMOU4434917 | D49: picked_up | E49: =VLOOKUP(J49,Sheet1!C:H,5,0) -> 未清关 | G49: 长滩 | H49: 2026-02-22 | I49: 2026-02-22 | J49: 25DSA6237
A50: 今日之前到港已提柜 | B50: BMOU4750406 | C50: =_xlfn.XLOOKUP($B50,Sheet1!$I:$I,Sheet1!AS:AS,0,0,1) -> 2026-02-19 14:42:00 | D50: returned_empty | E50: =VLOOKUP(J50,Sheet1!C:H,5,0) -> 已完成 | G50: 纽约 | H50: 2026-02-12 | I50: 2026-02-12 | J50: 25DSA06406 | L50: =_xlfn.XLOOKUP(B50,Sheet1!I:I,Sheet1!BB:BB,0,0,1) -> 2026-02-26 14:14:00
A51: 今日之前到港已提柜 | B51: BMOU5954723 | D51: picked_up | E51: =VLOOKUP(J51,Sheet1!C:H,5,0) -> 未清关 | G51: 纽约 | H51: 2026-02-13 | I51: 2026-02-15 | J51: 25DSA5998
A52: 今日之前到港已提柜 | B52: BMOU6025461 | C52: =_xlfn.XLOOKUP($B52,Sheet1!$I:$I,Sheet1!AS:AS,0,0,1) -> 2026-01-27 00:00:00 | D52: returned_empty | E52: =VLOOKUP(J52,Sheet1!C:H,5,0) -> 已完成 | G52: 长滩 | H52: 2026-01-24 | I52: 2026-01-24 | J52: 25DSA6216 | L52: =_xlfn.XLOOKUP(B52,Sheet1!I:I,Sheet1!BB:BB,0,0,1) -> 2026-02-02 00:00:00
A53: 今日之前到港已提柜 | B53: CAAU5182798 | D53: picked_up | E53: =VLOOKUP(J53,Sheet1!C:H,5,0) -> 已完成 | G53: 萨凡纳 | H53: 2026-02-14 | I53: 2026-02-14 | J53: 25DSA6172
A54: 今日之前到港已提柜 | B54: CAAU5298366 | C54: =_xlfn.XLOOKUP($B54,Sheet1!$I:$I,Sheet1!AS:AS,0,0,1) -> 2026-02-10 08:55:00 | D54: returned_empty | E54: =VLOOKUP(J54,Sheet1!C:H,5,0) -> 已完成 | G54: 萨凡纳 | H54: 2026-02-06 | I54: 2026-02-05 | J54: 25DSA6121 | L54: =_xlfn.XLOOKUP(B54,Sheet1!I:I,Sheet1!BB:BB,0,0,1) -> 2026-02-12 15:46:00
A55: 今日之前到港已提柜 | B55: CAAU5306327 | C55: =_xlfn.XLOOKUP($B55,Sheet1!$I:$I,Sheet1!AS:AS,0,0,1) -> 2026-02-10 00:00:00 | D55: returned_empty | E55: =VLOOKUP(J55,Sheet1!C:H,5,0) -> 已完成 | G55: 洛杉矶 | H55: 2026-02-04 | I55: 2026-02-03 | J55: 25DSA6148 | L55: =_xlfn.XLOOKUP(B55,Sheet1!I:I,Sheet1!BB:BB,0,0,1) -> 2026-02-16 07:09:00
A56: 今日之前到港已提柜 | B56: CAAU5871117 | D56: picked_up | E56: =VLOOKUP(J56,Sheet1!C:H,5,0) -> 已完成 | G56: 纽约 | H56: 2026-02-13 | I56: 2026-02-15 | J56: 25DSA06427
A57: 今日之前到港已提柜 | B57: CAAU6398884 | D57: picked_up | E57: =VLOOKUP(J57,Sheet1!C:H,5,0) -> 已完成 | G57: 洛杉矶 | H57: 2026-02-18 | I57: 2026-02-18 | J57: 25DSA6071
A58: 今日之前到港已提柜 | B58: CAIU4403602 | C58: =_xlfn.XLOOKUP($B58,Sheet1!$I:$I,Sheet1!AS:AS,0,0,1) -> 2026-02-09 00:00:00 | D58: returned_empty | E58: =VLOOKUP(J58,Sheet1!C:H,5,0) -> 已完成 | G58: 洛杉矶 | H58: 2026-02-07 | I58: 2026-02-07 | J58: 25DSA06487 | L58: =_xlfn.XLOOKUP(B58,Sheet1!I:I,Sheet1!BB:BB,0,0,1) -> 2026-02-18 00:00:00
A59: 今日之前到港已提柜 | B59: CAIU4443591 | D59: picked_up | E59: =VLOOKUP(J59,Sheet1!C:H,5,0) -> 未清关 | G59: 纽约 | H59: 2026-02-12 | I59: 2026-02-12 | J59: 25DSA06418
A60: 今日之前到港已提柜 | B60: CAIU7764152 | D60: picked_up | E60: =VLOOKUP(J60,Sheet1!C:H,5,0) -> 已完成 | G60: 萨凡纳 | H60: 2026-02-15 | I60: 2026-02-15 | J60: 25DSA5854
A61: 今日之前到港已提柜 | B61: CAIU8752480 | C61: =_xlfn.XLOOKUP($B61,Sheet1!$I:$I,Sheet1!AS:AS,0,0,1) -> 2026-02-09 00:00:00 | D61: returned_empty | E61: =VLOOKUP(J61,Sheet1!C:H,5,0) -> 已完成 | G61: 长滩 | H61: 2026-02-03 | I61: 2026-02-03 | J61: 25DSA5674 | L61: =_xlfn.XLOOKUP(B61,Sheet1!I:I,Sheet1!BB:BB,0,0,1) -> 2026-02-12 00:00:00
A62: 今日之前到港已提柜 | B62: CAIU9847256 | C62: =_xlfn.XLOOKUP($B62,Sheet1!$I:$I,Sheet1!AS:AS,0,0,1) -> 2026-01-28 00:00:00 | D62: returned_empty | E62: =VLOOKUP(J62,Sheet1!C:H,5,0) -> 已完成 | G62: 长滩 | H62: 2026-01-24 | I62: 2026-01-24 | J62: 25DSA6217 | L62: =_xlfn.XLOOKUP(B62,Sheet1!I:I,Sheet1!BB:BB,0,0,1) -> 2026-01-29 00:00:00
A63: 今日之前到港已提柜 | B63: CAJU5303664 | C63: =_xlfn.XLOOKUP($B63,Sheet1!$I:$I,Sheet1!AS:AS,0,0,1) -> 2026-02-12 00:00:00 | D63: returned_empty | E63: =VLOOKUP(J63,Sheet1!C:H,5,0) -> 未清关 | G63: 洛杉矶 | H63: 2026-02-11 | I63: 2026-02-10 | J63: 25DSA5947 | L63: =_xlfn.XLOOKUP(B63,Sheet1!I:I,Sheet1!BB:BB,0,0,1) -> 2026-02-18 15:20:00
A64: 今日之前到港已提柜 | B64: CIPU5045140 | C64: =_xlfn.XLOOKUP($B64,Sheet1!$I:$I,Sheet1!AS:AS,0,0,1) -> 2026-02-12 00:00:00 | D64: returned_empty | E64: =VLOOKUP(J64,Sheet1!C:H,5,0) -> 已完成 | G64: 洛杉矶 | H64: 2026-02-11 | I64: 2026-02-10 | J64: 25DSA06517 | L64: =_xlfn.XLOOKUP(B64,Sheet1!I:I,Sheet1!BB:BB,0,0,1) -> 2026-02-23 19:01:00
A65: 今日之前到港已提柜 | B65: FFAU1739261 | C65: =_xlfn.XLOOKUP($B65,Sheet1!$I:$I,Sheet1!AS:AS,0,0,1) -> 2026-02-04 00:00:00 | D65: returned_empty | E65: =VLOOKUP(J65,Sheet1!C:H,5,0) -> 已完成 | G65: 长滩 | H65: 2026-02-01 | I65: 2026-02-01 | J65: 25DSA6214 | L65: =_xlfn.XLOOKUP(B65,Sheet1!I:I,Sheet1!BB:BB,0,0,1) -> 2026-02-11 00:00:00
A66: 今日之前到港已提柜 | B66: FFAU1999660 | C66: =_xlfn.XLOOKUP($B66,Sheet1!$I:$I,Sheet1!AS:AS,0,0,1) -> 2026-02-09 00:00:00 | D66: returned_empty | E66: =VLOOKUP(J66,Sheet1!C:H,5,0) -> 已完成 | G66: 洛杉矶 | H66: 2026-02-07 | I66: 2026-02-07 | J66: 25DSA06485 | L66: =_xlfn.XLOOKUP(B66,Sheet1!I:I,Sheet1!BB:BB,0,0,1) -> 2026-02-18 00:00:00
A67: 今日之前到港已提柜 | B67: FFAU2353416 | C67: =_xlfn.XLOOKUP($B67,Sheet1!$I:$I,Sheet1!AS:AS,0,0,1) -> 2026-02-09 00:00:00 | D67: returned_empty | E67: =VLOOKUP(J67,Sheet1!C:H,5,0) -> 已完成 | G67: 长滩 | H67: 2026-02-03 | I67: 2026-02-03 | J67: 25DSA06478 | L67: =_xlfn.XLOOKUP(B67,Sheet1!I:I,Sheet1!BB:BB,0,0,1) -> 2026-02-18 00:00:00
A68: 今日之前到港已提柜 | B68: FFAU7097390 | C68: =_xlfn.XLOOKUP($B68,Sheet1!$I:$I,Sheet1!AS:AS,0,0,1) -> 2026-02-12 00:00:00 | D68: returned_empty | E68: =VLOOKUP(J68,Sheet1!C:H,5,0) -> 未清关 | G68: 洛杉矶 | H68: 2026-02-11 | I68: 2026-02-10 | J68: 25DSA06519 | L68: =_xlfn.XLOOKUP(B68,Sheet1!I:I,Sheet1!BB:BB,0,0,1) -> 2026-02-21 12:30:00
A69: 今日之前到港已提柜 | B69: FSCU8280139 | C69: =_xlfn.XLOOKUP($B69,Sheet1!$I:$I,Sheet1!AS:AS,0,0,1) -> 2026-02-10 16:44:56 | D69: returned_empty | E69: =VLOOKUP(J69,Sheet1!C:H,5,0) -> 已完成 | G69: 萨凡纳 | H69: 2026-02-06 | I69: 2026-02-05 | J69: 25DSA6162 | L69: =_xlfn.XLOOKUP(B69,Sheet1!I:I,Sheet1!BB:BB,0,0,1) -> 2026-02-14 09:58:00
A70: 今日之前到港已提柜 | B70: FSCU8356738 | C70: =_xlfn.XLOOKUP($B70,Sheet1!$I:$I,Sheet1!AS:AS,0,0,1) -> 2026-02-09 00:00:00 | D70: returned_empty | E70: =VLOOKUP(J70,Sheet1!C:H,5,0) -> 已完成 | G70: 长滩 | H70: 2026-02-03 | I70: 2026-02-03 | J70: 25DSA06481 | L70: =_xlfn.XLOOKUP(B70,Sheet1!I:I,Sheet1!BB:BB,0,0,1) -> 2026-02-11 00:00:00
A71: 今日之前到港已提柜 | B71: GAOU6230589 | C71: =_xlfn.XLOOKUP($B71,Sheet1!$I:$I,Sheet1!AS:AS,0,0,1) -> 2026-02-13 23:59:59 | D71: returned_empty | E71: =VLOOKUP(J71,Sheet1!C:H,5,0) -> 未清关 | G71: 萨凡纳 | H71: 2026-02-11 | I71: 2026-02-10 | J71: 25DSA6019 | L71: =_xlfn.XLOOKUP(B71,Sheet1!I:I,Sheet1!BB:BB,0,0,1) -> 2026-02-20 07:20:00
A72: 今日之前到港已提柜 | B72: HASU4164360 | C72: =_xlfn.XLOOKUP($B72,Sheet1!$I:$I,Sheet1!AS:AS,0,0,1) -> 2026-02-19 23:59:59 | D72: returned_empty | E72: =VLOOKUP(J72,Sheet1!C:H,5,0) -> 已完成 | G72: 萨凡纳 | H72: 2026-02-14 | I72: 2026-02-14 | J72: 25DSA6169 | L72: =_xlfn.XLOOKUP(B72,Sheet1!I:I,Sheet1!BB:BB,0,0,1) -> 2026-02-25 06:03:00
... A78: 今日之前到港已提柜 | B78: HASU4908522 | C78: =_xlfn.XLOOKUP($B78,Sheet1!$I:$I,Sheet1!AS:AS,0,0,1) -> 2026-02-12 00:00:00 | D78: returned_empty | E78: =VLOOKUP(J78,Sheet1!C:H,5,0) -> 未清关 | G78: 洛杉矶 | H78: 2026-02-11 | I78: 2026-02-10 | J78: 25DSA5948 | L78: =_xlfn.XLOOKUP(B78,Sheet1!I:I,Sheet1!BB:BB,0,0,1) -> 2026-02-18 07:29:00
...

Sheet Sheet2
A1: CAAU9221491 | B1: at_port | C1: 46084 | D1: eta_dest_port | E1: planned_pickup_date | K1: =VLOOKUP(L1,A:A,1,0) -> #N/A | L1: TGBU7946700 | M1: 46043 | N1: 25DSA6036 | O1: MEDUYM654982 | P1: 40HC | Q1: 在途 | R1: 否 | S1: 否 | T1: 萨凡纳 | U1: 在途 | V1: 46082 | W1: - | X1: - | Y1: 未清关 | AA1: 46080.443
A2: MRKU4378672 | B2: at_port | C2: 46084 | D2: 46082.333 | E2: 46085 | F2: =_xlfn.XLOOKUP(A2,Sheet1!I:I,Sheet1!H:H,0,,) -> 已卸船/火车 | H2: =VLOOKUP(I2,A:A,1,0) -> BEAU5730626 | I2: BEAU5730626 | K2: =VLOOKUP(L2,A:A,1,0) -> #N/A | L2: TLLU8797772 | M2: 46036 | N2: 25DSA6008 | O2: MEDUW7873567 | P2: 40HC | Q2: 在途 | R2: 否 | S2: 否 | T2: USNYC | U2: 在途 | V2: 46083 | W2: - | X2: - | Y2: 未清关 | AA2: 46080.443
A3: MRSU8517995 | B3: at_port | C3: 46084 | D3: 46082.333 | E3: 46085 | F3: =_xlfn.XLOOKUP(A3,Sheet1!I:I,Sheet1!H:H,0,,) -> 已卸船/火车 | H3: =VLOOKUP(I3,A:A,1,0) -> CAAU9221491 | I3: CAAU9221491 | K3: =VLOOKUP(L3,A:A,1,0) -> #N/A | L3: FFAU2763072 | M3: 46036 | N3: 25DSA6007 | O3: MEDUW7873575 | P3: 40HC | Q3: 在途 | R3: 否 | S3: 否 | T3: USNYC | U3: 在途 | V3: 46083 | W3: - | X3: - | Y3: 未清关 | AA3: 46080.443
A4: MRSU8794834 | B4: at_port | C4: 46084 | D4: 46082.333 | E4: 46085 | F4: =_xlfn.XLOOKUP(A4,Sheet1!I:I,Sheet1!H:H,0,,) -> 已到目的港 | H4: =VLOOKUP(I4,A:A,1,0) -> CAIU7235539 | I4: CAIU7235539 | K4: =VLOOKUP(L4,A:A,1,0) -> #N/A | L4: CAIU4821074 | M4: 46044 | N4: 25DSA5866 | O4: MEDUYM944136 | P4: 40HC | Q4: 在途 | R4: 否 | S4: 否 | T4: USNYC | U4: 在途 | V4: 46086 | W4: - | X4: - | Y4: 未清关 | AA4: 46080.443
A5: CAIU9970363 | B5: at_port | C5: 46083 | D5: 46087 | E5: 46086 | F5: =_xlfn.XLOOKUP(A5,Sheet1!I:I,Sheet1!H:H,0,,) -> 已卸船/火车 | H5: =VLOOKUP(I5,A:A,1,0) -> CAIU9970363 | I5: CAIU9970363 | K5: =VLOOKUP(L5,A:A,1,0) -> #N/A | L5: MSDU8471840 | M5: 46050 | N5: 25DSA5750 | O5: MEDUWK151340 | P5: 40HC | Q5: 在途 | R5: 否 | S5: 否 | T5: USNYC | U5: 在途 | V5: 46085 | W5: - | X5: - | Y5: 未清关 | AA5: 46080.443
A6: FSCU8507808 | B6: at_port | C6: 46083 | D6: 46082.25 | E6: 46086 | F6: =_xlfn.XLOOKUP(A6,Sheet1!I:I,Sheet1!H:H,0,,) -> 已卸船/火车 | H6: =VLOOKUP(I6,A:A,1,0) -> FSCU8507808 | I6: FSCU8507808 | K6: =VLOOKUP(L6,A:A,1,0) -> #N/A | L6: GCXU5052946 | M6: 46046 | N6: 25DSA06354 | O6: NBOZUX974700 | P6: 40HC | Q6: 在途 | R6: 否 | S6: 否 | T6: 萨凡纳 | U6: 在途 | V6: 46082.25 | W6: - | X6: - | Y6: 未清关 | AA6: 46080.443
A7: HMMU4016860 | B7: at_port | C7: 46083 | D7: 46087 | E7: 46086 | F7: =_xlfn.XLOOKUP(A7,Sheet1!I:I,Sheet1!H:H,0,,) -> 已卸船/火车 | H7: =VLOOKUP(I7,A:A,1,0) -> GCXU5599790 | I7: GCXU5599790 | K7: =VLOOKUP(L7,A:A,1,0) -> #N/A | L7: HMMU6111526 | M7: 46046 | N7: 25DSA06353 | O7: NBOZXUW26400 | P7: 40HC | Q7: 在途 | R7: 否 | S7: 否 | T7: 萨凡纳 | U7: 在途 | V7: 46082.25 | W7: - | X7: - | Y7: 未清关 | AA7: 46080.443
A8: HMMU4139490 | B8: at_port | C8: 46083 | D8: 46109 | E8: 46086 | F8: =_xlfn.XLOOKUP(A8,Sheet1!I:I,Sheet1!H:H,0,,) -> 已卸船/火车 | H8: =VLOOKUP(I8,A:A,1,0) -> HASU4405826 | I8: HASU4405826 | K8: =VLOOKUP(L8,A:A,1,0) -> #N/A | L8: UETU6078224 | M8: 46049 | N8: 25DSA6254 | O8: MEDUWT658814 | P8: 40HC | Q8: 在途 | R8: 否 | S8: 否 | T8: 萨凡纳 | U8: 在途 | V8: 46086 | W8: - | X8: - | Y8: 未清关 | AA8: 46080.443
A9: HMMU6350686 | B9: at_port | C9: 46083 | D9: 46085.896 | E9: 46090 | F9: =_xlfn.XLOOKUP(A9,Sheet1!I:I,Sheet1!H:H,0,,) -> 已卸船/火车 | H9: =VLOOKUP(I9,A:A,1,0) -> HMMU4016860 | I9: HMMU4016860 | K9: =VLOOKUP(L9,A:A,1,0) -> #N/A | L9: TEMU8187188 | M9: 46049 | N9: 25DSA6253 | O9: MEDUWT658822 | P9: 40HC | Q9: 在途 | R9: 否 | S9: 否 | T9: 萨凡纳 | U9: 在途 | V9: 46086 | W9: - | X9: - | Y9: 未清关 | AA9: 46080.443
A10: HMMU6552584 | B10: at_port | C10: 46083 | D10: 46085.896 | E10: 46090 | F10: =_xlfn.XLOOKUP(A10,Sheet1!I:I,Sheet1!H:H,0,,) -> 已卸船/火车 | H10: =VLOOKUP(I10,A:A,1,0) -> HMMU4139490 | I10: HMMU4139490 | K10: =VLOOKUP(L10,A:A,1,0) -> #N/A | L10: UETU6865976 | M10: 46049 | N10: 25DSA6252 | O10: MEDUWT658848 | P10: 40HC | Q10: 在途 | R10: 否 | S10: 否 | T10: 萨凡纳 | U10: 在途 | V10: 46086 | W10: - | X10: - | Y10: 未清关 | AA10: 46080.443
A11: HMMU6595800 | B11: at_port | C11: 46083 | D11: 46085.896 | E11: 46090 | F11: =_xlfn.XLOOKUP(A11,Sheet1!I:I,Sheet1!H:H,0,,) -> 已卸船/火车 | H11: =VLOOKUP(I11,A:A,1,0) -> HMMU4181756 | I11: HMMU4181756 | K11: =VLOOKUP(L11,A:A,1,0) -> #N/A | L11: MSMU4392884 | M11: 46049 | N11: 25DSA6251 | O11: MEDUWT658863 | P11: 40HC | Q11: 在途 | R11: 否 | S11: 否 | T11: 萨凡纳 | U11: 在途 | V11: 46086 | W11: - | X11: - | Y11: 未清关 | AA11: 46080.443
A12: HMMU6671860 | B12: at_port | C12: 46083 | D12: 46085.896 | E12: 46090 | F12: =_xlfn.XLOOKUP(A12,Sheet1!I:I,Sheet1!H:H,0,,) -> 已卸船/火车 | H12: =VLOOKUP(I12,A:A,1,0) -> HMMU4753337 | I12: HMMU4753337 | K12: =VLOOKUP(L12,A:A,1,0) -> #N/A | L12: MRKU2809678 | M12: 46047 | N12: 25DSA06449 | O12: 277629219 | P12: 40HC | Q12: 在途 | R12: 否 | S12: 否 | T12: 纽瓦克 | U12: 在途 | V12: 46085.521 | W12: - | X12: - | Y12: 未清关 | AA12: 46080.392
A13: HMMU6855472 | B13: at_port | C13: 46083 | D13: 46085.896 | E13: 46090 | F13: =_xlfn.XLOOKUP(A13,Sheet1!I:I,Sheet1!H:H,0,,) -> 已卸船/火车 | H13: =VLOOKUP(I13,A:A,1,0) -> HMMU6350686 | I13: HMMU6350686 | K13: =VLOOKUP(L13,A:A,1,0) -> #N/A | L13: GESU6765687 | M13: 46040 | N13: 25DSA06443 | O13: 277629215 | P13: 40HC | Q13: 在途 | R13: 否 | S13: 否 | T13: 纽瓦克 | U13: 在途 | V13: 46081.312 | W13: - | X13: - | Y13: 未清关 | AA13: 46080.392
A14: HMMU6874528 | B14: at_port | C14: 46083 | D14: 46085.896 | E14: 46090 | F14: =_xlfn.XLOOKUP(A14,Sheet1!I:I,Sheet1!H:H,0,,) -> 已卸船/火车 | H14: =VLOOKUP(I14,A:A,1,0) -> HMMU6552584 | I14: HMMU6552584 | K14: =VLOOKUP(L14,A:A,1,0) -> #N/A | L14: TCNU5084329 | M14: 46051 | N14: 25DSA06402 | O14: NBOZ80W86900 | P14: 40HC | Q14: 在途 | R14: 否 | S14: 否 | T14: USNYC | U14: 在途 | V14: 46079.896 | W14: - | X14: - | Y14: 未清关 | AA14: 46080.441
A15: HMMU6947630 | B15: at_port | C15: 46083 | D15: 46086 | E15: 46091 | F15: =_xlfn.XLOOKUP(A15,Sheet1!I:I,Sheet1!H:H,0,,) -> 已卸船/火车 | H15: =VLOOKUP(I15,A:A,1,0) -> HMMU6595800 | I15: HMMU6595800 | K15: =VLOOKUP(L15,A:A,1,0) -> #N/A | L15: TCKU6101299 | M15: 46051 | N15: 25DSA06397 | O15: NBOZRZ059400 | P15: 40HC | Q15: 在途 | R15: 否 | S15: 否 | T15: USNYC | U15: 在途 | V15: 46079.896 | W15: - | X15: - | Y15: 未清关 | AA15: 46080.441
A16: HMMU7164789 | B16: at_port | C16: 46083 | D16: 46086 | E16: 46091 | F16: =_xlfn.XLOOKUP(A16,Sheet1!I:I,Sheet1!H:H,0,,) -> 已卸船/火车 | H16: =VLOOKUP(I16,A:A,1,0) -> HMMU6671860 | I16: HMMU6671860 | K16: =VLOOKUP(L16,A:A,1,0) -> #N/A | L16: HMMU4753091 | M16: 46051 | N16: 25DSA06398 | O16: NBOZRLQ11200 | P16: 40HC | Q16: 在途 | R16: 否 | S16: 否 | T16: USNYC | U16: 在途 | V16: 46079.896 | W16: - | X16: - | Y16: 未清关 | AA16: 46080.441
A17: KOCU4690071 | B17: at_port | C17: 46083 | D17: 46086 | E17: 46091 | F17: =_xlfn.XLOOKUP(A17,Sheet1!I:I,Sheet1!H:H,0,,) -> 已卸船/火车 | H17: =VLOOKUP(I17,A:A,1,0) -> HMMU6855472 | I17: HMMU6855472 | K17: =VLOOKUP(L17,A:A,1,0) -> #N/A | L17: HMMU4753785 | M17: 46051 | N17: 25DSA06395 | O17: NBOZU6F41300 | P17: 40HC | Q17: 在途 | R17: 否 | S17: 否 | T17: USNYC | U17: 在途 | V17: 46079.896 | W17: - | X17: - | Y17: 未清关 | AA17: 46080.441
A18: KOCU4714466 | B18: at_port | C18: 46083 | D18: 46086 | E18: 46091 | F18: =_xlfn.XLOOKUP(A18,Sheet1!I:I,Sheet1!H:H,0,,) -> 已卸船/火车 | H18: =VLOOKUP(I18,A:A,1,0) -> HMMU6874528 | I18: HMMU6874528 | K18: =VLOOKUP(L18,A:A,1,0) -> #N/A | L18: HMMU4745368 | M18: 46051 | N18: 25DSA06396 | O18: NBOZS2229600 | P18: 40HC | Q18: 在途 | R18: 否 | S18: 否 | T18: USNYC | U18: 在途 | V18: 46079.896 | W18: - | X18: - | Y18: 未清关 | AA18: 46080.441
A19: KOCU5082923 | B19: at_port | C19: 46083 | D19: 46089 | E19: 46092 | F19: =_xlfn.XLOOKUP(A19,Sheet1!I:I,Sheet1!H:H,0,,) -> 已卸船/火车 | H19: =VLOOKUP(I19,A:A,1,0) -> HMMU6947630 | I19: HMMU6947630 | K19: =VLOOKUP(L19,A:A,1,0) -> #N/A | L19: HMMU4745835 | M19: 46051 | N19: 25DSA06394 | O19: NBOZUQH86200 | P19: 40HC | Q19: 在途 | R19: 否 | S19: 否 | T19: USNYC | U19: 在途 | V19: 46079.896 | W19: - | X19: - | Y19: 未清关 | AA19: 46080.441
A20: TEMU7307910 | B20: at_port | C20: 46083 | D20: 46088.333 | E20: 46092 | F20: =_xlfn.XLOOKUP(A20,Sheet1!I:I,Sheet1!H:H,0,,) -> 已卸船/火车 | H20: =VLOOKUP(I20,A:A,1,0) -> HMMU7135055 | I20: HMMU7135055 | K20: =VLOOKUP(L20,A:A,1,0) -> #N/A | L20: HMMU4745542 | M20: 46051 | N20: 25DSA06393 | O20: NBOZX8617100 | P20: 40HC | Q20: 在途 | R20: 否 | S20: 否 | T20: USNYC | U20: 在途 | V20: 46079.896 | W20: - | X20: - | Y20: 未清关 | AA20: 46080.441
A21: TLLU5814475 | B21: at_port | C21: 46083 | D21: 46093.333 | E21: 46094 | F21: =_xlfn.XLOOKUP(A21,Sheet1!I:I,Sheet1!H:H,0,,) -> 已卸船/火车 | H21: =VLOOKUP(I21,A:A,1,0) -> HMMU7164789 | I21: HMMU7164789 | K21: =VLOOKUP(L21,A:A,1,0) -> #N/A | L21: HMMU4751360 | M21: 46051 | N21: 25DSA06392 | O21: NBOZXRZ17000 | P21: 40HC | Q21: 在途 | R21: 否 | S21: 否 | T21: USNYC | U21: 在途 | V21: 46079.896 | W21: - | X21: - | Y21: 未清关 | AA21: 46080.441
A22: TXGU7910130 | B22: at_port | C22: 46083 | F22: =_xlfn.XLOOKUP(A22,Sheet1!I:I,Sheet1!H:H,0,,) -> 已卸船/火车 | H22: =VLOOKUP(I22,A:A,1,0) -> KOCU4690071 | I22: KOCU4690071 | K22: =VLOOKUP(L22,A:A,1,0) -> #N/A | L22: HMMU6985239 | M22: 46051 | N22: 25DSA06391 | O22: NBOZZEC04100 | P22: 40HC | Q22: 在途 | R22: 否 | S22: 否 | T22: USNYC | U22: 在途 | V22: 46079.896 | W22: - | X22: - | Y22: 未清关 | AA22: 46080.441
A23: TXGU8539620 | B23: at_port | C23: 46083 | F23: =_xlfn.XLOOKUP(A23,Sheet1!I:I,Sheet1!H:H,0,,) -> 已卸船/火车 | H23: =VLOOKUP(I23,A:A,1,0) -> KOCU4714466 | I23: KOCU4714466 | K23: =VLOOKUP(L23,A:A,1,0) -> #N/A | L23: MSMU7303216 | M23: 46042 | N23: 25DSA06390 | O23: MEDUKY811052 | P23: 40HC | Q23: 在途 | R23: 否 | S23: 否 | T23: USNYC | U23: 在途 | V23: 46083 | W23: - | X23: - | Y23: 未清关 | AA23: 46080.441
A24: GCXU5599790 | B24: at_port | C24: 46080 | F24: =_xlfn.XLOOKUP(A24,Sheet1!I:I,Sheet1!H:H,0,,) -> 已到目的港 | H24: =VLOOKUP(I24,A:A,1,0) -> KOCU5032943 | I24: KOCU5032943 | K24: =VLOOKUP(L24,A:A,1,0) -> #N/A | L24: MSCU5159429 | M24: 46042 | N24: 25DSA06389 | O24: MEDUKY811060 | P24: 40HC | Q24: 在途 | R24: 否 | S24: 否 | T24: USNYC | U24: 在途 | V24: 46083 | W24: - | X24: - | Y24: 未清关 | AA24: 46080.441
A25: HASU4405826 | B25: at_port | C25: 46080 | F25: =_xlfn.XLOOKUP(A25,Sheet1!I:I,Sheet1!H:H,0,,) -> 已到目的港 | H25: =VLOOKUP(I25,A:A,1,0) -> KOCU5073074 | I25: KOCU5073074 | K25: =VLOOKUP(L25,A:A,1,0) -> #N/A | L25: FFAU4147142 | M25: 46042 | N25: 25DSA06388 | O25: MEDUKY811086 | P25: 40HC | Q25: 在途 | R25: 否 | S25: 否 | T25: USNYC | U25: 在途 | V25: 46083 | W25: - | X25: - | Y25: 未清关 | AA25: 46080.441
A26: MSKU0627486 | B26: at_port | C26: 46080 | F26: =_xlfn.XLOOKUP(A26,Sheet1!I:I,Sheet1!H:H,0,,) -> 已到目的港 | H26: =VLOOKUP(I26,A:A,1,0) -> KOCU5082923 | I26: KOCU5082923 | K26: =VLOOKUP(L26,A:A,1,0) -> #N/A | L26: MEDU4945651 | M26: 46042 | N26: 25DSA06387 | O26: MEDUKY811094 | P26: 40HC | Q26: 在途 | R26: 否 | S26: 否 | T26: USNYC | U26: 在途 | V26: 46083 | W26: - | X26: - | Y26: 未清关 | AA26: 46080.441
A27: MRSU9475512 | B27: at_port | C27: 46079 | F27: =_xlfn.XLOOKUP(A27,Sheet1!I:I,Sheet1!H:H,0,,) -> 已到目的港 | H27: =VLOOKUP(I27,A:A,1,0) -> MRKU2750203 | I27: MRKU2750203 | K27: =VLOOKUP(L27,A:A,1,0) -> #N/A | L27: MSBU5540642 | M27: 46042 | N27: 25DSA06385 | O27: MEDUKY811177 | P27: 40HC | Q27: 在途 | R27: 否 | S27: 否 | T27: USNYC | U27: 在途 | V27: 46083 | W27: - | X27: - | Y27: 未清关 | AA27: 46080.443
A28: MSNU5178675 | B28: at_port | C28: 46079 | F28: =_xlfn.XLOOKUP(A28,Sheet1!I:I,Sheet1!H:H,0,,) -> 已卸船/火车 | H28: =VLOOKUP(I28,A:A,1,0) -> MRKU4378672 | I28: MRKU4378672 | K28: =VLOOKUP(L28,A:A,1,0) -> #N/A | L28: TCNU6363077 | M28: 46047 | N28: 25DSA06490 | O28: 277629319 | P28: 40HC | Q28: 在途 | R28: 否 | S28: 否 | T28: 纽瓦克 | U28: 在途 | V28: 46085.521 | W28: - | X28: - | Y28: 未清关 | AA28: 46080.392
A29: TGBU6878468 | B29: at_port | C29: 46079 | F29: =_xlfn.XLOOKUP(A29,Sheet1!I:I,Sheet1!H:H,0,,) -> 已到目的港 | H29: =VLOOKUP(I29,A:A,1,0) -> MRKU4501107 | I29: MRKU4501107 | K29: =VLOOKUP(L29,A:A,1,0) -> #N/A | L29: SEKU6886060 | M29: 46047 | N29: 25DSA06491 | O29: 277629318 | P29: 40HC | Q29: 在途 | R29: 否 | S29: 否 | T29: 纽瓦克 | U29: 在途 | V29: 46085.521 | W29: - | X29: - | Y29: 未清关 | AA29: 46080.392
A30: UETU7804928 | B30: at_port | C30: 46079 | F30: =_xlfn.XLOOKUP(A30,Sheet1!I:I,Sheet1!H:H,0,,) -> 已卸船/火车 | H30: =VLOOKUP(I30,A:A,1,0) -> MRKU5180737 | I30: MRKU5180737 | K30: =VLOOKUP(L30,A:A,1,0) -> #N/A | L30: TCNU1456942 | M30: 46040 | N30: 25DSA06447 | O30: 277629211 | P30: 40HC | Q30: 在途 | R30: 否 | S30: 否 | T30: 纽瓦克 | U30: 在途 | V30: 46081.312 | W30: - | X30: - | Y30: 未清关 | AA30: 46080.392
A31: MRKU2750203 | B31: at_port | C31: 46078 | F31: =_xlfn.XLOOKUP(A31,Sheet1!I:I,Sheet1!H:H,0,,) -> 已卸船/火车 | H31: =VLOOKUP(I31,A:A,1,0) -> MRKU5557646 | I31: MRKU5557646 | K31: =VLOOKUP(L31,A:A,1,0) -> #N/A | L31: SUDU5723824 | M31: 46040 | N31: 25DSA06446 | O31: 277629212 | P31: 40HC | Q31: 在途 | R31: 否 | S31: 否 | T31: 纽瓦克 | U31: 在途 | V31: 46081.312 | W31: - | X31: - | Y31: 未清关 | AA31: 46080.392
A32: MRKU5180737 | B32: at_port | C32: 46078 | F32: =_xlfn.XLOOKUP(A32,Sheet1!I:I,Sheet1!H:H,0,,) -> 已卸船/火车 | H32: =VLOOKUP(I32,A:A,1,0) -> MRSU3186214 | I32: MRSU3186214 | K32: =VLOOKUP(L32,A:A,1,0) -> #N/A | L32: MRSU7851230 | M32: 46041 | N32: 25DSA06444 | O32: 277629214 | P32: 40HC | Q32: 在途 | R32: 否 | S32: 否 | T32: 纽瓦克 | U32: 在途 | V32: 46081.312 | W32: - | X32: - | Y32: 未清关 | AA32: 46080.392
A33: CAIU7235539 | B33: at_port | C33: 46077 | F33: =_xlfn.XLOOKUP(A33,Sheet1!I:I,Sheet1!H:H,0,,) -> 已卸船/火车 | H33: =VLOOKUP(I33,A:A,1,0) -> MRSU4494227 | I33: MRSU4494227 | K33: =VLOOKUP(L33,A:A,1,0) -> #N/A | L33: MRSU3111787 | M33: 46047 | N33: 25DSA06451 | O33: 277629217 | P33: 40HC | Q33: 在途 | R33: 否 | S33: 否 | T33: 纽瓦克 | U33: 在途 | V33: 46085.521 | W33: - | X33: - | Y33: 未清关 | AA33: 46080.392
A34: HMMU4181756 | B34: at_port | C34: 46077 | F34: =_xlfn.XLOOKUP(A34,Sheet1!I:I,Sheet1!H:H,0,,) -> 已卸船/火车 | H34: =VLOOKUP(I34,A:A,1,0) -> MRSU8517995 | I34: MRSU8517995 | K34: =VLOOKUP(L34,A:A,1,0) -> #N/A | L34: MRKU5071551 | M34: 46047 | N34: 25DSA06452 | O34: 277629216 | P34: 40HC | Q34: 在途 | R34: 否 | S34: 否 | T34: 纽瓦克 | U34: 在途 | V34: 46085.521 | W34: - | X34: - | Y34: 未清关 | AA34: 46080.392
A35: HMMU4753337 | B35: at_port | C35: 46077 | F35: =_xlfn.XLOOKUP(A35,Sheet1!I:I,Sheet1!H:H,0,,) -> 已卸船/火车 | H35: =VLOOKUP(I35,A:A,1,0) -> MRSU8794834 | I35: MRSU8794834 | K35: =VLOOKUP(L35,A:A,1,0) -> #N/A | L35: MRSU3098622 | M35: 46047 | N35: 25DSA06448 | O35: 277629220 | P35: 40HC | Q35: 在途 | R35: 否 | S35: 否 | T35: 纽瓦克 | U35: 在途 | V35: 46085.521 | W35: - | X35: - | Y35: 未清关 | AA35: 46080.392
A36: HMMU7135055 | B36: at_port | C36: 46077 | F36: =_xlfn.XLOOKUP(A36,Sheet1!I:I,Sheet1!H:H,0,,) -> 已卸船/火车 | H36: =VLOOKUP(I36,A:A,1,0) -> MRSU9475512 | I36: MRSU9475512 | K36: =VLOOKUP(L36,A:A,1,0) -> #N/A | L36: MRSU5038915 | M36: 46047 | N36: 25DSA06450 | O36: 277629218 | P36: 40HC | Q36: 在途 | R36: 否 | S36: 否 | T36: 纽瓦克 | U36: 在途 | V36: 46085.521 | W36: - | X36: - | Y36: 未清关 | AA36: 46080.392
A37: KOCU5032943 | B37: at_port | C37: 46077 | F37: =_xlfn.XLOOKUP(A37,Sheet1!I:I,Sheet1!H:H,0,,) -> 已卸船/火车 | H37: =VLOOKUP(I37,A:A,1,0) -> MSKU0627486 | I37: MSKU0627486 | K37: =VLOOKUP(L37,A:A,1,0) -> #N/A | L37: FFAU6704057 | M37: 46040 | N37: 25DSA06445 | O37: 277629213 | P37: 40HC | Q37: 在途 | R37: 否 | S37: 否 | T37: 纽瓦克 | U37: 在途 | V37: 46081.312 | W37: - | X37: - | Y37: 未清关 | AA37: 46080.392
A38: KOCU5073074 | B38: at_port | C38: 46077 | F38: =_xlfn.XLOOKUP(A38,Sheet1!I:I,Sheet1!H:H,0,,) -> 已卸船/火车 | H38: =VLOOKUP(I38,A:A,1,0) -> MSKU1739536 | I38: MSKU1739536 | K38: =VLOOKUP(L38,A:A,1,0) -> #N/A | L38: MAGU5260319 | M38: 46042 | N38: 25DSA5490 | O38: 265105671 | P38: 40HC | Q38: 在途 | R38: 否 | S38: 否 | T38: 纽瓦克 | U38: 在途 | V38: 46083.292 | W38: - | X38: - | Y38: 未清关 | AA38: 46080.441
A39: MSKU1739536 | B39: at_port | C39: 46077 | F39: =_xlfn.XLOOKUP(A39,Sheet1!I:I,Sheet1!H:H,0,,) -> 已卸船/火车 | H39: =VLOOKUP(I39,A:A,1,0) -> MSKU9347315 | I39: MSKU9347315 | K39: =VLOOKUP(L39,A:A,1,0) -> #N/A | L39: TCKU6115857 | M39: 46046 | N39: 25DSA06360 | O39: NBOZCSW75100 | P39: 40HC | Q39: 在途 | R39: 否 | S39: 否 | T39: 萨凡纳 | U39: 在途 | V39: 46082.25 | W39: - | X39: - | Y39: 未清关 | AA39: 46080.443
A40: MSKU9347315 | B40: at_port | C40: 46077 | F40: =_xlfn.XLOOKUP(A40,Sheet1!I:I,Sheet1!H:H,0,,) -> 已卸船/火车 | H40: =VLOOKUP(I40,A:A,1,0) -> MSMU6370164 | I40: MSMU6370164 | K40: =VLOOKUP(L40,A:A,1,0) -> #N/A | L40: KOCU4631844 | M40: 46046 | N40: 25DSA06359 | O40: NBOZJGJ69900 | P40: 40HC | Q40: 在途 | R40: 否 | S40: 否 | T40: 萨凡纳 | U40: 在途 | V40: 46082.25 | W40: - | X40: - | Y40: 未清关 | AA40: 46080.443
...

Sheet Sheet1
A1: 是否查验 | B1: 销往国家 | C1: 备货单号 | E1: 主备货单号 | F1: 备货单状态 | G1: 清关状态 | H1: 物流状态 | I1: 集装箱号 | J1: 提单号 | K1: 船公司 | L1: 柜型 | M1: Wayfair SPO | N1: 是否装配件 | O1: 特殊货物体积 | P1: 起运港 | Q1: 目的港 | R1: 起运港货代公司 | S1: 入库仓库组 | T1: 预计到港日期 | U1: ETA修正 | V1: 出运日期 | W1: 计划清关日期 | X1: 实际清关日期 | Y1: 目的港清关公司 | Z1: 是否开箱 | AA1: 清关单据状态 | AB1: 全部生成日期 | AC1: 异常原因(清关信息表） | AD1: 途经港 | AE1: 途经港到达日期 | AF1: 目的港到达日期 | AG1: 目的港卸船/火车日期 | AH1: 目的港码头 | AI1: 最后免费日期 | AJ1: 是否预提 | AK1: 运输方式 | AL1: 目的港卡车 | AM1: 仓库(计划) | AN1: 仓库(实际) | AO1: 入库日期 | AP1: 最晚提柜日期 | AQ1: 计划提柜日期 | AR1: 提柜日期 | AS1: 最晚送仓日期 | AT1: 计划送仓日期 | AU1: 卸柜方式(计划) | AV1: 卸柜方式（实际） | AW1: 最晚卸柜日期 | AX1: 计划卸柜日期 | AY1: 卸空日期 | AZ1: 最晚还箱日期 | BA1: 计划还箱日期 | BB1: 还箱日期 | BC1: 备注(物流信息表） | BD1: 提柜通知 | BE1: 货柜承运商 | BF1: 卸柜门 | BG1: 卸柜公司 | BH1: 通知取空日期 | BI1: 取空时间 | BJ1: 备注(仓库信息表) | BK1: 价格条款 | BL1: 箱数合计 | BM1: 体积合计(m3) | BN1: 毛重合计(KG) | BO1: 出运总价 | BP1: 议付金额FOB | BQ1: 议付金额CIF | BR1: 议付金额 | BS1: 海运费币种 | BT1: 标准海运费金额 | BU1: 目的地 | BV1: 船名 | BW1: 航次 | BX1: ISF申报状态 | BY1: ISF申报日期 | BZ1: 免堆期(天) | CA1: 场内免箱期(天) | CB1: 场外免箱期(天) | CC1: 放单日期 | CD1: 传递日期 | CE1: 进港日期 | CF1: MBL SCAC | CG1: MBL Number | CH1: HBL SCAC | CI1: HBL Number | CJ1: AMS Number | CK1: 进火车堆场日期 | CL1: 进卡车堆场日期 | CM1: WMS入库状态 | CN1: EBS入库状态 | CO1: WMS Confirm Date | CP1: 母船出运日期 | CQ1: 母船船名 | CR1: 母船船次 | CS1: 含要求打托产品 | CT1: 采购贸易模式
A2: 否 | B2: AOSOM LLC | C2: 25DSA0524 | D2: 25DSA0524 | E2: 25DSA0524 | F2: 已出运 | G2: 未清关 | H2: 已提柜 | I2: MRKU4376920 | J2: 277629038 | K2: MAERSK | L2: 40HQ | N2: 否 | O2: 0 | P2: 宁波 | Q2: 纽瓦克 | R2: 简达物流集团股份有限公司 | S2: New Jersey Warehouse Group | T2: 2026-02-18 18:30:00 | U2: 2026-02-18 18:30:00 | V2: 2026-01-11 00:00:00 | Y2: Sen Mart International Inc. | Z2: 否 | AA2: 部分生成 | AF2: 2026-02-18 20:46:00 | AG2: 2026-02-19 08:34:00 | AH2: APM TERMINAL - BERTH 88 E425 | AI2: 2026-02-27 18:10:25 | AJ2: 否 | AK2: 卡车 | AL2: JK EXPRESS USA INC | AM2: AOSOM NJ-1 | AP2: 2026-02-27 23:59:59 | AQ2: 2026-02-23 12:00:00 | AR2: 2026-02-26 15:41:00 | AS2: 2026-02-23 12:00:00 | AT2: 2026-02-23 12:00:00 | AU2: Drop off | AW2: 2026-02-24 12:00:00 | AX2: 2026-02-23 00:00:00 | AZ2: 2026-03-09 23:59:59 | BA2: 2026-02-24 00:00:00 | BK2: FOB | BL2: 368 | BM2: 63.93 | BN2: 21640 | BO2: 34997.82 | BP2: 34997.82 | BQ2: 34997.82 | BR2: 0 | BS2: 美元 | BT2: 2639 | BV2: VIENNA EXPRESS | BW2: 602E | BX2: 已申报 | BY2: 2026-01-01 21:01:35 | CD2: 2026-01-11 20:16:20 | CG2: 277629038 | CH2: MAEU | CI2: MAEU277629038 | CJ2: MAEU277629038 | CP2: 2026-01-14 00:00:00 | CT2: B2B：需换单
A3: 否 | B3: AOSOM LLC | C3: 25DSA0525 | D3: 25DSA0525 | E3: 25DSA0525 | F3: 已出运 | G3: 未清关 | H3: 已提柜 | I3: SUDU6657440 | J3: 277629067 | K3: MAERSK | L3: 40HQ | N3: 否 | O3: 0 | P3: 宁波 | Q3: 纽瓦克 | R3: 简达物流集团股份有限公司 | S3: New Jersey Warehouse Group | T3: 2026-02-18 18:30:00 | U3: 2026-02-18 18:30:00 | V3: 2026-01-11 00:00:00 | Y3: Sen Mart International Inc. | Z3: 否 | AA3: 部分生成 | AF3: 2026-02-18 20:46:00 | AG3: 2026-02-19 14:20:00 | AH3: APM TERMINAL - BERTH 88 E425 | AI3: 2026-02-27 18:13:38 | AJ3: 否 | AK3: 卡车 | AL3: JK EXPRESS USA INC | AM3: AOSOM NJ-1 | AP3: 2026-02-27 23:59:59 | AQ3: 2026-02-23 12:00:00 | AR3: 2026-02-26 15:34:00 | AS3: 2026-02-23 12:00:00 | AT3: 2026-02-23 12:00:00 | AU3: Drop off | AW3: 2026-02-24 12:00:00 | AX3: 2026-02-23 00:00:00 | AZ3: 2026-03-09 23:59:59 | BA3: 2026-02-24 00:00:00 | BK3: FOB | BL3: 335 | BM3: 65.25 | BN3: 9001 | BO3: 17507.01 | BP3: 17507.01 | BQ3: 17507.01 | BR3: 0 | BS3: 美元 | BT3: 2639 | BV3: VIENNA EXPRESS | BW3: 602E | BX3: 已申报 | BY3: 2025-12-31 21:01:54 | CD3: 2026-01-11 20:15:42 | CG3: 277629067 | CH3: MAEU | CI3: MAEU277629067 | CJ3: MAEU277629067 | CP3: 2026-01-14 00:00:00 | CT3: B2B：需换单
A4: 否 | B4: AOSOM LLC | C4: 25DSA0526 | D4: 25DSA0526 | E4: 25DSA0526 | F4: 已出运 | G4: 未清关 | H4: 已提柜 | I4: TCKU7094070 | J4: 277629066 | K4: MAERSK | L4: 40HQ | N4: 否 | O4: 0 | P4: 宁波 | Q4: 纽瓦克 | R4: 简达物流集团股份有限公司 | S4: New Jersey Warehouse Group | T4: 2026-02-18 18:30:00 | U4: 2026-02-18 18:30:00 | V4: 2026-01-11 00:00:00 | Y4: SODARISE INC | Z4: 否 | AA4: 部分生成 | AF4: 2026-02-18 20:46:00 | AG4: 2026-02-19 08:11:00 | AH4: APM TERMINAL - BERTH 88 E425 | AI4: 2026-02-27 18:09:28 | AJ4: 否 | AK4: 卡车 | AL4: SHANGHAI FLYING FISH SUPPLY CHAIN TECHNOLOGY CO.,L | AM4: AOSOM NJ-1 | AP4: 2026-02-27 23:59:59 | AQ4: 2026-02-23 12:00:00 | AR4: 2026-02-26 10:38:00 | AS4: 2026-02-23 12:00:00 | AT4: 2026-02-23 12:00:00 | AU4: Drop off | AW4: 2026-02-24 12:00:00 | AX4: 2026-02-23 00:00:00 | AZ4: 2026-03-09 23:59:59 | BA4: 2026-02-24 00:00:00 | BK4: FOB | BL4: 339 | BM4: 68.25 | BN4: 9555.6 | BO4: 20854.32 | BP4: 20854.32 | BQ4: 20854.32 | BR4: 0 | BS4: 美元 | BT4: 2639 | BV4: VIENNA EXPRESS | BW4: 602E | BX4: 已申报 | BY4: 2025-12-31 21:01:54 | CD4: 2026-01-11 20:15:42 | CG4: 277629066 | CH4: MAEU | CI4: MAEU277629066 | CJ4: MAEU277629066 | CP4: 2026-01-14 00:00:00 | CT4: B2B：需换单
A5: 否 | B5: AOSOM LLC | C5: 25DSA0541 | D5: 25DSA0541 | E5: 25DSA0541 | F5: 已出运 | G5: 未清关 | H5: 已到中转港 | I5: CAAU9304575 | J5: 264862233 | K5: MAERSK | L5: 40HQ | N5: 否 | O5: 0 | P5: 天津新港 | Q5: 纽瓦克 | R5: 宁波天图翼联物流科技有限公司 | S5: New Jersey Warehouse Group | T5: 2026-03-07 08:00:00 | U5: 2026-03-07 08:00:00 | V5: 2026-01-15 00:00:00 | Y5: SODARISE INC | Z5: 否 | AA5: 全部传递 | AD5: 釜山 | AE5: 2026-01-18 13:44:00 | AJ5: 否 | AK5: 卡车 | AL5: JK EXPRESS USA INC | AM5: AOSOM NJ-1 | AP5: 2026-03-12 23:59:59 | AQ5: 2026-03-11 12:00:00 | AS5: 2026-03-11 12:00:00 | AT5: 2026-03-11 12:00:00 | AU5: Drop off | AW5: 2026-03-12 12:00:00 | AX5: 2026-03-13 00:00:00 | AZ5: 2026-03-20 23:59:59 | BA5: 2026-03-16 00:00:00 | BK5: FOB | BL5: 438 | BM5: 66.07 | BN5: 12640.1 | BO5: 24527.62 | BP5: 24527.62 | BQ5: 24527.62 | BR5: 0 | BS5: 美元 | BT5: 2639 | BV5: X-PRESS CARINA | BW5: 601W | BX5: 已申报 | BY5: 2026-01-06 21:01:39 | CD5: 2026-01-15 20:21:06 | CG5: 264862233 | CH5: MAEU | CI5: MAEU264862233 | CJ5: MAEU264862233 | CP5: 2026-01-29 00:00:00 | CT5: B2B：需换单
A6: 否 | B6: AOSOM LLC | C6: 25DSA0556 | D6: 25DSA0556 | E6: 25DSA0556 | F6: 已出运 | G6: 未清关 | H6: 已卸船/火车 | I6: MRSU3186214 | J6: 277629065 | K6: MAERSK | L6: 40HQ | N6: 否 | O6: 0 | P6: 宁波 | Q6: 纽瓦克 | R6: 简达物流集团股份有限公司 | S6: New Jersey Warehouse Group | T6: 2026-02-18 18:30:00 | U6: 2026-02-18 18:30:00 | V6: 2026-01-11 00:00:00 | Y6: Sen Mart International Inc. | Z6: 否 | AA6: 未生成 | AF6: 2026-02-18 20:46:00 | AG6: 2026-02-19 11:31:00 | AH6: APM TERMINAL - BERTH 88 E425 | AI6: 2026-02-27 18:09:49 | AJ6: 否 | AK6: 卡车 | AL6: SHANGHAI FLYING FISH SUPPLY CHAIN TECHNOLOGY CO.,L | AM6: AOSOM NJ-1 | AP6: 2026-02-27 23:59:59 | AQ6: 2026-02-23 12:00:00 | AS6: 2026-02-23 12:00:00 | AT6: 2026-02-23 12:00:00 | AU6: Drop off | AW6: 2026-02-24 12:00:00 | AX6: 2026-02-23 00:00:00 | AZ6: 2026-03-04 23:59:59 | BA6: 2026-02-24 00:00:00 | BK6: FOB | BL6: 399 | BM6: 66.6 | BN6: 12897 | BO6: 23148.35 | BP6: 23148.35 | BQ6: 23148.35 | BR6: 0 | BS6: 美元 | BT6: 2639 | BV6: VIENNA EXPRESS | BW6: 602E | BX6: 已申报 | BY6: 2025-12-31 21:01:54 | CD6: 2026-01-11 20:15:41 | CG6: 277629065 | CH6: MAEU | CI6: MAEU277629065 | CJ6: MAEU277629065 | CP6: 2026-01-14 00:00:00 | CT6: B2B：需换单
A7: 否 | B7: AOSOM LLC | C7: 25DSA0557 | D7: 25DSA0557 | E7: 25DSA0557 | F7: 已出运 | G7: 未清关 | H7: 已卸船/火车 | I7: MRKU4501107 | J7: 277629064 | K7: MAERSK | L7: 40HQ | N7: 否 | O7: 0 | P7: 宁波 | Q7: 纽瓦克 | R7: 简达物流集团股份有限公司 | S7: New Jersey Warehouse Group | T7: 2026-02-18 18:30:00 | U7: 2026-02-18 18:30:00 | V7: 2026-01-11 00:00:00 | Y7: Sen Mart International Inc. | Z7: 否 | AA7: 部分生成 | AF7: 2026-02-18 20:46:00 | AG7: 2026-02-18 23:10:00 | AH7: APM TERMINAL - BERTH 88 E425 | AI7: 2026-02-27 19:20:18 | AJ7: 否 | AK7: 卡车 | AL7: JK EXPRESS USA INC | AM7: AOSOM NJ-1 | AP7: 2026-02-27 23:59:59 | AQ7: 2026-02-23 12:00:00 | AS7: 2026-02-23 12:00:00 | AT7: 2026-02-23 12:00:00 | AU7: Drop off | AW7: 2026-02-24 12:00:00 | AX7: 2026-02-23 00:00:00 | AZ7: 2026-03-04 23:59:59 | BA7: 2026-02-24 00:00:00 | BK7: FOB | BL7: 1197 | BM7: 65.19 | BN7: 9998.7 | BO7: 23233.39 | BP7: 23233.39 | BQ7: 23233.39 | BR7: 0 | BS7: 美元 | BT7: 2639 | BV7: VIENNA EXPRESS | BW7: 602E | BX7: 已申报 | BY7: 2025-12-31 21:01:55 | CD7: 2026-01-11 20:15:43 | CG7: 277629064 | CH7: MAEU | CI7: MAEU277629064 | CJ7: MAEU277629064 | CP7: 2026-01-14 00:00:00 | CT7: B2B：需换单
A8: 否 | B8: AOSOM LLC | C8: 25DSA0799 | D8: 25DSA0799 | E8: 25DSA0799 | F8: 已出运 | G8: 未清关 | H8: 已卸船/火车 | I8: MRKU4378672 | J8: 263145683 | K8: MAERSK | L8: 40HQ | N8: 否 | O8: 0 | P8: 丹戎帕拉帕斯 | Q8: 萨凡纳 | R8: SOUTHEAST INTERNATIONAL LOGISTICS MALAYSIA SDN BHD | S8: Atlanta warehouse group | T8: 2026-02-26 04:30:00 | U8: 2026-02-26 04:30:00 | V8: 2026-01-04 00:00:00 | W8: 2026-02-24 23:59:59 | Y8: Sen Mart International Inc. | Z8: 否 | AA8: 全部生成 | AB8: 2026-02-23 19:48:29 | AD8: 上海 | AE8: 2026-01-11 01:09:00 | AF8: 2026-02-26 04:15:00 | AG8: 2026-02-26 14:09:00 | AH8: GARDEN CITY MARINE TERMINAL | AI8: 2026-03-05 23:59:59 | AJ8: 否 | AK8: 卡车 | AL8: Portguys Logistics Llc | AM8: AOSOM GA-1 | AP8: 2026-03-05 23:59:59 | AQ8: 2026-03-03 23:59:59 | AS8: 2026-03-03 23:59:59 | AT8: 2026-03-03 23:59:59 | AU8: Drop off | AW8: 2026-03-04 23:59:59 | AX8: 2026-03-05 23:59:59 | AZ8: 2026-03-12 23:59:59 | BA8: 2026-03-06 23:59:59 | BK8: FOB | BL8: 497 | BM8: 64.57 | BN8: 9159.4 | BO8: 23233.4 | BP8: 23233.4 | BQ8: 23233.4 | BR8: 0 | BS8: 美元 | BT8: 2639 | BV8: TRANCURA | BW8: 550N | BX8: 已申报 | BY8: 2026-02-23 21:01:46 | CG8: 263145683 | CH8: MAEU | CI8: MAEU263145683 | CJ8: MAEU263145683 | CP8: 2026-01-13 00:00:00 | CT8: 常规
A9: 否 | B9: AOSOM LLC | C9: 25DSA5378 | D9: 25DSA5378 | E9: 25DSA5378 | F9: 已出运 | G9: 未清关 | H9: 已卸船/火车 | I9: MSMU6370164 | J9: 181AY0263395881A1 | K9: MSC | L9: 40HQ | N9: 否 | O9: 0 | P9: 盐田 | Q9: 长滩 | R9: 宁波天图翼联物流科技有限公司 | S9: Los warehouse group | T9: 2026-02-22 16:00:00 | U9: 2026-02-22 16:00:00 | V9: 2026-01-24 00:00:00 | Y9: Sen Mart International Inc. | Z9: 否 | AA9: 全部生成 | AB9: 2026-02-13 20:12:07 | AF9: 2026-02-22 12:01:14 | AG9: 2026-02-23 00:00:00 | AH9: LONG BEACH PIER T TERMINAL | AI9: 2026-02-27 18:00:26 | AJ9: 否 | AK9: 卡车 | AL9: SHANGHAI FLYING FISH SUPPLY CHAIN TECHNOLOGY CO.,L | AM9: AOSOM CA-1 | AP9: 2026-02-27 23:59:59 | AQ9: 2026-02-24 00:00:00 | AS9: 2026-02-24 00:00:00 | AT9: 2026-02-24 00:00:00 | AU9: Drop off | AW9: 2026-02-24 00:00:00 | AX9: 2026-02-24 00:00:00 | AZ9: 2026-03-19 23:59:59 | BA9: 2026-02-25 00:00:00 | BK9: FOB | BL9: 1531 | BM9: 63.73 | BN9: 9906.5 | BO9: 63821.93 | BP9: 63821.93 | BQ9: 63821.93 | BR9: 0 | BS9: 美元 | BT9: 1764 | BV9: MSC TANZANIA | BW9: FV603N | BX9: 已申报 | BY9: 2026-01-20 21:02:02 | CD9: 2026-01-24 20:03:20 | CG9: MEDUYM944201 | CH9: MEDU | CI9: MEDUYM944201 | CJ9: MEDUYM944201 | CP9: 2026-02-04 00:00:00 | CT9: B2B：需换单
A10: 否 | B10: AOSOM LLC | C10: 25DSA5487 | D10: 25DSA5487 | E10: 25DSA5487 | F10: 已出运 | G10: 未清关 | H10: 已到目的港 | I10: TGBU6878468 | J10: 181AY0253379936A1 | K10: MSC | L10: 40HQ | N10: 否 | O10: 0 | P10: 盐田 | Q10: 萨凡纳 | R10: 宁波天图翼联物流科技有限公司 | S10: Atlanta warehouse group | T10: 2026-02-25 00:00:00 | U10: 2026-02-25 00:00:00 | V10: 2026-01-05 00:00:00 | W10: 2026-02-18 23:59:59 | Y10: Sen Mart International Inc. | Z10: 否 | AA10: 全部传递 | AF10: 2026-02-24 17:32:04 | AJ10: 否 | AK10: 卡车 | AL10: LFT TRANSPORTATION INC | AM10: AOSOM GA-1 | AP10: 2026-02-27 23:59:59 | AQ10: 2026-02-26 23:59:59 | AS10: 2026-02-26 23:59:59 | AT10: 2026-02-26 23:59:59 | AU10: Drop off | AW10: 2026-02-27 23:59:59 | AX10: 2026-02-27 23:59:59 | AZ10: 2026-03-11 23:59:59 | BA10: 2026-02-28 23:59:59 | BK10: FOB | BL10: 840 | BM10: 70.01 | BN10: 14184.8 | BO10: 24042.36 | BP10: 24042.36 | BQ10: 24042.36 | BR10: 0 | BS10: 美元 | BT10: 2906 | BV10: ZIM MOUNT VINSON | BW10: 8E | BX10: 未申报 | BY10: 2026-01-04 21:01:50 | CD10: 2026-01-06 20:26:31 | CG10: MEDUYM511174 | CH10: MEDU | CI10: MEDUYM511174 | CJ10: MEDUYM511174 | CP10: 2026-01-05 00:00:00 | CT10: B2B：需换单
A11: 否 | B11: AOSOM LLC | C11: 25DSA5490 | D11: 25DSA5490 | E11: 25DSA5490 | F11: 已出运 | G11: 未清关 | H11: 已出运 | I11: MAGU5260319 | J11: 265105671 | K11: MAERSK | L11: 40HQ | N11: 否 | O11: 0 | P11: 盐田 | Q11: 纽瓦克 | R11: 宁波天图翼联物流科技有限公司 | S11: New Jersey Warehouse Group | T11: 2026-03-02 07:00:00 | U11: 2026-03-02 07:00:00 | V11: 2026-01-20 00:00:00 | Y11: SODARISE INC | Z11: 否 | AA11: 全部传递 | AJ11: 否 | AK11: 卡车 | AL11: JK EXPRESS USA INC | AM11: AOSOM NJ-1 | AP11: 2026-03-05 23:59:59 | AQ11: 2026-03-05 12:00:00 | AS11: 2026-03-05 12:00:00 | AT11: 2026-03-05 12:00:00 | AU11: Drop off | AW11: 2026-03-06 12:00:00 | AX11: 2026-03-06 00:00:00 | AZ11: 2026-03-16 23:59:59 | BA11: 2026-03-09 00:00:00 | BK11: FOB | BL11: 908 | BM11: 65.12 | BN11: 6396.5 | BO11: 17373.37 | BP11: 17373.37 | BQ11: 17373.37 | BR11: 0 | BS11: 美元 | BT11: 2639 | BV11: ANTWERPEN EXPRESS | BW11: 604E | BX11: 已申报 | BY11: 2026-01-16 21:02:33 | CD11: 2026-01-20 19:58:27 | CG11: 265105671 | CH11: MAEU | CI11: MAEU265105671 | CJ11: MAEU265105671 | CP11: 2026-01-21 00:00:00 | CT11: B2B：需换单
A12: 否 | B12: AOSOM LLC | C12: 25DSA5510 | D12: 25DSA5510 | E12: 25DSA5510 | F12: 已出运 | G12: 已完成 | H12: 已还箱 | I12: MSMU6212240 | J12: 181AY0253385374A1 | K12: MSC | L12: 40HQ | N12: 否 | O12: 0 | P12: 盐田 | Q12: 纽约 | R12: 宁波天图翼联物流科技有限公司 | S12: New Jersey Warehouse Group | T12: 2026-02-12 00:00:00 | U12: 2026-02-12 00:00:00 | V12: 2026-01-03 00:00:00 | W12: 2026-01-30 23:59:59 | Y12: Sen Mart International Inc. | Z12: 否 | AA12: 部分生成 | AF12: 2026-02-12 16:49:10 | AG12: 2026-02-12 00:00:00 | AH12: PORT NEWARK CONTAINER TERMINAL | AI12: 2026-02-18 23:59:59 | AJ12: 否 | AK12: 卡车 | AL12: SHANGHAI FLYING FISH SUPPLY CHAIN TECHNOLOGY CO.,L | AM12: AOSOM NJ-1 | AN12: AOSOM NJ-1 | AO12: 2026-02-19 05:40:14 | AP12: 2026-02-18 23:59:59 | AQ12: 2026-02-15 21:10:35 | AR12: 2026-02-17 00:00:00 | AS12: 2026-02-15 21:10:35 | AT12: 2026-02-15 21:10:35 | AU12: Drop off | AW12: 2026-02-16 21:10:35 | AX12: 2026-02-17 00:00:00 | AZ12: 2026-03-12 23:59:59 | BA12: 2026-02-18 00:00:00 | BB12: 2026-02-19 00:00:00 | BK12: FOB | BL12: 767 | BM12: 66.5 | BN12: 7274.2 | BO12: 16854.46 | BP12: 16854.46 | BQ12: 16854.46 | BR12: 0 | BS12: 美元 | BT12: 3006.1 | BV12: PUSAN C | BW12: GU552W | BX12: 已申报 | BY12: 2025-12-27 21:01:58 | CD12: 2026-01-03 20:13:17 | CG12: MEDUYM653406 | CH12: MEDU | CI12: MEDUYM653406 | CJ12: MEDUYM653406 | CM12: WMS已完成 | CN12: 已入库 | CO12: 2026-02-18 11:33:41 | CP12: 2026-01-03 00:00:00 | CT12: B2B：需换单
A13: 否 | B13: AOSOM LLC | C13: 25DSA5511 | D13: 25DSA5511 | E13: 25DSA5511 | F13: 已出运 | G13: 未清关 | H13: 已到中转港 | I13: MSMU8485434 | J13: 181AY0253385444A1 | K13: MSC | L13: 40HQ | N13: 否 | O13: 0 | P13: 盐田 | Q13: 纽约 | R13: 宁波天图翼联物流科技有限公司 | S13: New Jersey Warehouse Group | T13: 2026-03-06 00:00:00 | U13: 2026-03-06 00:00:00 | V13: 2026-01-08 00:00:00 | W13: 2026-01-30 23:59:59 | Y13: Sen Mart International Inc. | Z13: 否 | AA13: 部分生成 | AD13: 釜山 | AE13: 2026-01-22 13:39:14 | AJ13: 否 | AK13: 卡车 | AL13: JK EXPRESS USA INC | AM13: AOSOM NJ-1 | AP13: 2026-03-11 23:59:59 | AQ13: 2026-03-05 12:00:00 | AS13: 2026-03-05 12:00:00 | AT13: 2026-03-05 12:00:00 | AU13: Drop off | AW13: 2026-03-06 12:00:00 | AX13: 2026-03-08 00:00:00 | AZ13: 2026-03-30 23:59:59 | BA13: 2026-03-09 00:00:00 | BK13: FOB | BL13: 697 | BM13: 66.8 | BN13: 7467.5 | BO13: 22115.34 | BP13: 22115.34 | BQ13: 22115.34 | BR13: 0 | BS13: 美元 | BT13: 2934.1 | BV13: MSC RACHELE | BW13: GU601W | BX13: 已申报 | BY13: 2026-01-04 21:01:51 | CD13: 2026-01-08 20:20:30 | CG13: MEDUYM654883 | CH13: MEDU | CI13: MEDUYM654883 | CJ13: MEDUYM654883 | CP13: 2026-01-11 00:00:00 | CT13: B2B：需换单
A14: 否 | B14: AOSOM LLC | C14: 25DSA5613 | D14: 25DSA5613 | E14: 25DSA5613 | F14: 已出运 | G14: 未清关 | H14: 已卸船/火车 | I14: BEAU5730626 | J14: 277629037 | K14: MAERSK | L14: 40HQ | N14: 否 | O14: 0 | P14: 宁波 | Q14: 纽瓦克 | R14: 简达物流集团股份有限公司 | S14: New Jersey Warehouse Group | T14: 2026-02-18 18:30:00 | U14: 2026-02-18 18:30:00 | V14: 2026-01-11 00:00:00 | Y14: Sen Mart International Inc. | Z14: 否 | AA14: 全部生成 | AB14: 2026-02-13 20:01:55 | AF14: 2026-02-18 20:46:00 | AG14: 2026-02-19 07:23:00 | AH14: APM TERMINAL - BERTH 88 E425 | AI14: 2026-02-27 18:05:58 | AJ14: 否 | AK14: 卡车 | AL14: JK EXPRESS USA INC | AM14: AOSOM NJ-1 | AP14: 2026-02-27 23:59:59 | AQ14: 2026-02-23 12:00:00 | AS14: 2026-02-23 12:00:00 | AT14: 2026-02-23 12:00:00 | AU14: Drop off | AW14: 2026-02-24 12:00:00 | AX14: 2026-02-25 00:00:00 | AZ14: 2026-03-04 23:59:59 | BA14: 2026-02-26 00:00:00 | BK14: FOB | BL14: 1475 | BM14: 67.43 | BN14: 14395 | BO14: 28360.3 | BP14: 28360.3 | BQ14: 28360.3 | BR14: 0 | BS14: 美元 | BT14: 2639 | BV14: VIENNA EXPRESS | BW14: 602E | BX14: 已申报 | BY14: 2026-01-01 21:01:35 | CD14: 2026-01-11 20:16:21 | CG14: 277629037 | CH14: MAEU | CI14: MAEU277629037 | CJ14: MAEU277629037 | CP14: 2026-01-14 00:00:00 | CT14: B2B：需换单
A15: 否 | B15: AOSOM LLC | C15: 25DSA5614 | D15: 25DSA5614 | E15: 25DSA5614 | F15: 已出运 | G15: 未清关 | H15: 已卸船/火车 | I15: MRSU4494227 | J15: 277629063 | K15: MAERSK | L15: 40HQ | N15: 否 | O15: 0 | P15: 宁波 | Q15: 纽瓦克 | R15: 简达物流集团股份有限公司 | S15: New Jersey Warehouse Group | T15: 2026-02-18 18:30:00 | U15: 2026-02-18 18:30:00 | V15: 2026-01-11 00:00:00 | Y15: Sen Mart International Inc. | Z15: 否 | AA15: 全部生成 | AB15: 2026-02-13 20:01:09 | AF15: 2026-02-18 20:46:00 | AG15: 2026-02-19 20:00:00 | AH15: APM TERMINAL - BERTH 88 E425 | AI15: 2026-02-27 18:09:02 | AJ15: 否 | AK15: 卡车 | AL15: JK EXPRESS USA INC | AM15: AOSOM NJ-1 | AP15: 2026-02-27 23:59:59 | AQ15: 2026-02-23 12:00:00 | AS15: 2026-02-23 12:00:00 | AT15: 2026-02-23 12:00:00 | AU15: Drop off | AW15: 2026-02-24 12:00:00 | AX15: 2026-02-25 00:00:00 | AZ15: 2026-03-04 23:59:59 | BA15: 2026-02-26 00:00:00 | BK15: FOB | BL15: 1089 | BM15: 65.53 | BN15: 13299 | BO15: 28587.02 | BP15: 28587.02 | BQ15: 28587.02 | BR15: 0 | BS15: 美元 | BT15: 2639 | BV15: VIENNA EXPRESS | BW15: 602E | BX15: 已申报 | BY15: 2025-12-31 21:01:55 | CD15: 2026-01-11 20:15:43 | CG15: 277629063 | CH15: MAEU | CI15: MAEU277629063 | CJ15: MAEU277629063 | CP15: 2026-01-14 00:00:00 | CT15: B2B：需换单
A16: 否 | B16: AOSOM LLC | C16: 25DSA5616 | D16: 25DSA5616 | E16: 25DSA5616 | F16: 已出运 | G16: 未清关 | H16: 已提柜 | I16: MRSU4349492 | J16: 277629062 | K16: MAERSK | L16: 40HQ | N16: 否 | O16: 0 | P16: 宁波 | Q16: 纽瓦克 | R16: 简达物流集团股份有限公司 | S16: New Jersey Warehouse Group | T16: 2026-02-18 18:30:00 | U16: 2026-02-18 18:30:00 | V16: 2026-01-11 00:00:00 | Y16: Sen Mart International Inc. | Z16: 否 | AA16: 全部生成 | AB16: 2026-02-13 20:01:10 | AF16: 2026-02-18 20:46:00 | AG16: 2026-02-19 08:19:00 | AH16: APM TERMINAL - BERTH 88 E425 | AI16: 2026-02-27 18:08:45 | AJ16: 否 | AK16: 卡车 | AL16: JK EXPRESS USA INC | AM16: AOSOM NJ-1 | AP16: 2026-02-27 23:59:59 | AQ16: 2026-02-23 12:00:00 | AR16: 2026-02-26 11:12:00 | AS16: 2026-02-23 12:00:00 | AT16: 2026-02-23 12:00:00 | AU16: Drop off | AW16: 2026-02-24 12:00:00 | AX16: 2026-02-25 00:00:00 | AZ16: 2026-03-09 23:59:59 | BA16: 2026-02-26 00:00:00 | BK16: FOB | BL16: 731 | BM16: 65.17 | BN16: 15909.5 | BO16: 23647.17 | BP16: 23647.17 | BQ16: 23647.17 | BR16: 0 | BS16: 美元 | BT16: 2639 | BV16: VIENNA EXPRESS | BW16: 602E | BX16: 已申报 | BY16: 2025-12-31 21:01:55 | CD16: 2026-01-11 20:15:44 | CG16: 277629062 | CH16: MAEU | CI16: MAEU277629062 | CJ16: MAEU277629062 | CP16: 2026-01-14 00:00:00 | CT16: B2B：需换单
A17: 否 | B17: AOSOM LLC | C17: 25DSA5662 | D17: 25DSA5662 | E17: 25DSA5662 | F17: 已出运 | G17: 已完成 | H17: 已还箱 | I17: MSKU9367522 | J17: 277629008 | K17: MAERSK | L17: 40HQ | N17: 否 | O17: 0 | P17: 宁波 | Q17: 萨凡纳 | R17: 简达物流集团股份有限公司 | S17: Atlanta warehouse group | T17: 2026-02-06 20:00:00 | U17: 2026-02-06 20:00:00 | V17: 2026-01-02 00:00:00 | W17: 2026-02-03 23:59:59 | Y17: Sen Mart International Inc. | Z17: 否 | AA17: 全部生成 | AB17: 2026-02-13 19:57:38 | AF17: 2026-02-05 11:10:00 | AG17: 2026-02-06 14:18:00 | AH17: GARDEN CITY MARINE TERMINAL | AI17: 2026-02-13 23:59:59 | AJ17: 否 | AK17: 卡车 | AL17: LFT TRANSPORTATION INC | AM17: AOSOM GA-1 | AN17: AOSOM GA-1 | AO17: 2026-02-15 15:39:17 | AP17: 2026-02-13 23:59:59 | AQ17: 2026-02-10 16:39:35 | AR17: 2026-02-10 16:39:35 | AS17: 2026-02-10 16:39:35 | AT17: 2026-02-10 16:39:35 | AU17: Drop off | AW17: 2026-02-11 16:39:35 | AX17: 2026-02-12 05:37:00 | AZ17: 2026-02-19 23:59:59 | BA17: 2026-02-13 05:37:00 | BB17: 2026-02-13 08:52:00 | BH17: 2026-02-15 16:00:16 | BK17: FOB | BL17: 410 | BM17: 66.8 | BN17: 13721 | BO17: 25242.8 | BP17: 25242.8 | BQ17: 25242.8 | BR17: 0 | BS17: 美元 | BT17: 2529 | BV17: MAERSK SINGAPORE | BW17: 552E | BX17: 已申报 | BY17: 2025-12-23 09:22:45 | CD17: 2026-01-03 02:14:45 | CG17: 277629008 | CH17: MAEU | CI17: MAEU277629008 | CJ17: MAEU277629008 | CM17: WMS已完成 | CN17: 已入库 | CO17: 2026-02-15 13:10:33 | CP17: 2026-01-03 00:00:00 | CT17: B2B：需换单
A18: 否 | B18: AOSOM LLC | C18: 25DSA5663 | D18: 25DSA5663 | E18: 25DSA5663 | F18: 已出运 | G18: 已完成 | H18: 已还箱 | I18: MRKU4027873 | J18: 277629005 | K18: MAERSK | L18: 40HQ | N18: 否 | O18: 0 | P18: 宁波 | Q18: 萨凡纳 | R18: 简达物流集团股份有限公司 | S18: Atlanta warehouse group | T18: 2026-02-06 20:00:00 | U18: 2026-02-06 20:00:00 | V18: 2026-01-02 00:00:00 | W18: 2026-02-03 23:59:59 | Y18: Sen Mart International Inc. | Z18: 否 | AA18: 全部生成 | AB18: 2026-02-13 19:57:39 | AF18: 2026-02-05 11:10:00 | AG18: 2026-02-05 22:22:00 | AH18: GARDEN CITY MARINE TERMINAL | AI18: 2026-02-12 23:59:59 | AJ18: 否 | AK18: 卡车 | AL18: LFT TRANSPORTATION INC | AM18: AOSOM GA-1 | AN18: AOSOM GA-1 | AO18: 2026-02-12 07:39:18 | AP18: 2026-02-12 23:59:59 | AQ18: 2026-02-07 12:42:00 | AR18: 2026-02-07 12:42:00 | AS18: 2026-02-07 12:42:00 | AT18: 2026-02-07 12:42:00 | AU18: Drop off | AW18: 2026-02-08 12:42:00 | AX18: 2026-02-11 05:37:00 | AZ18: 2026-02-18 23:59:59 | BA18: 2026-02-12 05:37:00 | BB18: 2026-02-12 07:24:00 | BK18: FOB | BL18: 734 | BM18: 66.45 | BN18: 6710 | BO18: 16123.98 | BP18: 16123.98 | BQ18: 16123.98 | BR18: 0 | BS18: 美元 | BT18: 2529 | BV18: MAERSK SINGAPORE | BW18: 552E | BX18: 已申报 | BY18: 2025-12-23 09:22:45 | CD18: 2026-01-03 02:14:46 | CG18: 277629005 | CH18: MAEU | CI18: MAEU277629005 | CJ18: MAEU277629005 | CM18: WMS已完成 | CN18: 已入库 | CO18: 2026-02-12 04:18:14 | CP18: 2026-01-03 00:00:00 | CT18: B2B：需换单
A19: 否 | B19: AOSOM LLC | C19: 25DSA5664 | D19: 25DSA5664 | E19: 25DSA5664 | F19: 已出运 | G19: 已完成 | H19: 已还箱 | I19: MSKU9486012 | J19: 277629004 | K19: MAERSK | L19: 40HQ | N19: 否 | O19: 0 | P19: 宁波 | Q19: 萨凡纳 | R19: 简达物流集团股份有限公司 | S19: Atlanta warehouse group | T19: 2026-02-06 20:00:00 | U19: 2026-02-06 20:00:00 | V19: 2026-01-02 00:00:00 | W19: 2026-02-03 23:59:59 | Y19: Sen Mart International Inc. | Z19: 否 | AA19: 全部生成 | AB19: 2026-02-13 19:56:29 | AF19: 2026-02-05 11:10:00 | AG19: 2026-02-06 01:37:00 | AH19: GARDEN CITY MARINE TERMINAL | AI19: 2026-02-13 23:59:59 | AJ19: 否 | AK19: 卡车 | AL19: LFT TRANSPORTATION INC | AM19: AOSOM GA-1 | AN19: AOSOM GA-1 | AO19: 2026-02-11 12:39:04 | AP19: 2026-02-13 23:59:59 | AQ19: 2026-02-07 11:00:00 | AR19: 2026-02-07 11:00:00 | AS19: 2026-02-07 11:00:00 | AT19: 2026-02-07 11:00:00 | AU19: Drop off | AW19: 2026-02-08 11:00:00 | AX19: 2026-02-11 05:37:00 | AZ19: 2026-02-18 23:59:59 | BA19: 2026-02-12 05:37:00 | BB19: 2026-02-12 05:42:00 | BH19: 2026-02-11 12:00:15 | BK19: FOB | BL19: 314 | BM19: 69.86 | BN19: 14341.5 | BO19: 28140.12 | BP19: 28140.12 | BQ19: 28140.12 | BR19: 0 | BS19: 美元 | BT19: 2529 | BV19: MAERSK SINGAPORE | BW19: 552E | BX19: 已申报 | BY19: 2025-12-22 21:01:58 | CD19: 2026-01-03 02:13:55 | CG19: 277629004 | CH19: MAEU | CI19: MAEU277629004 | CJ19: MAEU277629004 | CM19: WMS已完成 | CN19: 已入库 | CO19: 2026-02-11 10:27:29 | CP19: 2026-01-03 00:00:00 | CT19: B2B：需换单
A20: 否 | B20: AOSOM LLC | C20: 25DSA5674 | D20: 25DSA5674 | E20: 25DSA5674 | F20: 已出运 | G20: 已完成 | H20: 已还箱 | I20: CAIU8752480 | J20: 177QZJZJS109687 | K20: MSC | L20: 40HQ | N20: 否 | O20: 0 | P20: 上海 | Q20: 长滩 | R20: 宁波外运国际货运代理有限公司 | S20: Los warehouse group | T20: 2026-02-03 16:00:00 | U20: 2026-02-03 16:00:00 | V20: 2026-01-08 00:00:00 | W20: 2026-01-28 23:59:59 | Y20: Sen Mart International Inc. | Z20: 否 | AA20: 全部生成 | AB20: 2026-02-13 20:04:37 | AF20: 2026-02-03 14:52:02 | AG20: 2026-02-06 00:00:00 | AH20: TOTAL TERMINALS INTERNATIONAL (PIER T) | AI20: 2026-02-13 23:59:59 | AJ20: 否 | AK20: 卡车 | AL20: SHANGHAI FLYING FISH SUPPLY CHAIN TECHNOLOGY CO.,L | AM20: AOSOM CA-1 | AN20: AOSOM CA-1 | AO20: 2026-02-13 14:38:57 | AP20: 2026-02-13 23:59:59 | AQ20: 2026-02-09 00:00:00 | AR20: 2026-02-11 00:00:00 | AS20: 2026-02-09 00:00:00 | AT20: 2026-02-09 00:00:00 | AU20: Drop off | AW20: 2026-02-09 00:00:00 | AX20: 2026-02-09 00:00:00 | AZ20: 2026-03-06 23:59:59 | BA20: 2026-02-10 00:00:00 | BB20: 2026-02-12 00:00:00 | BK20: CIF | BL20: 710 | BM20: 66.44 | BN20: 11951 | BO20: 19976.7 | BP20: 19976.7 | BQ20: 21723.31 | BR20: 1746.63 | BS20: 美元 | BT20: 1744 | BV20: MSC GAIA | BW20: GO601N | BX20: 已申报 | BY20: 2026-01-05 21:01:55 | CD20: 2026-01-09 20:22:48 | CG20: MEDUW7698550 | CH20: MEDU | CI20: MEDUW7698550 | CJ20: MEDUW7698550 | CM20: WMS已完成 | CN20: 已入库 | CO20: 2026-02-13 09:02:03 | CP20: 2026-01-13 00:00:00 | CT20: B2B：需换单
A21: 否 | B21: AOSOM LLC | C21: 25DSA5677 | D21: 25DSA5677 | E21: 25DSA5677 | F21: 已出运 | G21: 未清关 | H21: 已卸船/火车 | I21: MRKU5180737 | J21: 264862165 | K21: MAERSK | L21: 40HQ | N21: 否 | O21: 0 | P21: 青岛 | Q21: 纽瓦克 | R21: 宁波天图翼联物流科技有限公司 | S21: New Jersey Warehouse Group | T21: 2026-02-21 06:00:00 | U21: 2026-02-21 06:00:00 | V21: 2026-01-04 00:00:00 | W21: 2026-02-04 23:59:59 | Y21: Sen Mart International Inc. | Z21: 否 | AA21: 部分生成 | AD21: 釜山 | AE21: 2026-01-06 22:38:00 | AF21: 2026-02-21 07:08:00 | AG21: 2026-02-21 08:58:00 | AH21: APM TERMINAL - BERTH 88 E425 | AI21: 2026-02-27 16:55:48 | AJ21: 否 | AK21: 卡车 | AL21: SHANGHAI FLYING FISH SUPPLY CHAIN TECHNOLOGY CO.,L | AM21: AOSOM NJ-1 | AP21: 2026-02-27 23:59:59 | AQ21: 2026-02-25 12:00:00 | AS21: 2026-02-25 12:00:00 | AT21: 2026-02-25 12:00:00 | AU21: Drop off | AW21: 2026-02-26 12:00:00 | AX21: 2026-02-27 00:00:00 | AZ21: 2026-03-06 23:59:59 | BA21: 2026-03-02 00:00:00 | BK21: FOB | BL21: 938 | BM21: 63.96 | BN21: 9037 | BO21: 19329.54 | BP21: 19329.54 | BQ21: 19329.54 | BR21: 0 | BS21: 美元 | BT21: 2639 | BV21: GUNDE MAERSK | BW21: 601E | BX21: 已申报 | BY21: 2025-12-31 21:01:55 | CD21: 2026-01-04 20:22:24 | CG21: 264862165 | CH21: MAEU | CI21: MAEU264862165 | CJ21: MAEU264862165 | CP21: 2026-01-12 00:00:00 | CT21: B2B：需换单
A22: 否 | B22: AOSOM LLC | C22: 25DSA5686 | D22: 25DSA5686 | E22: 25DSA5686 | F22: 已出运 | G22: 未清关 | H22: 已到中转港 | I22: MRSU3733332 | J22: 263704967 | K22: MAERSK | L22: 40HQ | N22: 否 | O22: 0 | P22: 厦门港 | Q22: 纽瓦克 | R22: 宁波天图翼联物流科技有限公司 | S22: New Jersey Warehouse Group | T22: 2026-03-28 08:00:00 | U22: 2026-03-28 08:00:00 | V22: 2026-01-24 00:00:00 | Y22: Sen Mart International Inc. | Z22: 否 | AA22: 全部传递 | AD22: 釜山 | AE22: 2026-01-27 12:29:00 | AJ22: 否 | AK22: 卡车 | AP22: 2026-04-02 23:59:59 | AZ22: 2026-04-08 23:59:59 | BK22: FOB | BL22: 464 | BM22: 69.28 | BN22: 10888 | BO22: 26238.9 | BP22: 26238.9 | BQ22: 26238.9 | BR22: 0 | BS22: 美元 | BT22: 2639 | BV22: SYNERGY KEELUNG | BW22: 603N | BX22: 已申报 | BY22: 2026-01-20 21:02:02 | CD22: 2026-01-24 20:03:21 | CG22: 263704967 | CH22: MAEU | CI22: MAEU263704967 | CJ22: MAEU263704967 | CP22: 2026-02-02 00:00:00 | CT22: B2B：需换单
A23: 否 | B23: AOSOM LLC | C23: 25DSA5687 | D23: 25DSA5687 | E23: 25DSA5687 | F23: 已出运 | G23: 未清关 | H23: 已卸船/火车 | I23: MRKU2750203 | J23: 262777253 | K23: MAERSK | L23: 40HQ | N23: 否 | O23: 0 | P23: 厦门港 | Q23: 纽瓦克 | R23: 宁波天图翼联物流科技有限公司 | S23: New Jersey Warehouse Group | T23: 2026-02-21 06:00:00 | U23: 2026-02-21 06:00:00 | V23: 2026-01-03 00:00:00 | W23: 2026-02-04 23:59:59 | Y23: Sen Mart International Inc. | Z23: 否 | AA23: 全部生成 | AB23: 2026-02-13 19:59:09 | AD23: 釜山 | AE23: 2026-01-06 15:22:00 | AF23: 2026-02-21 07:08:00 | AG23: 2026-02-21 10:48:00 | AH23: APM TERMINAL - BERTH 88 E425 | AI23: 2026-02-27 16:51:55 | AJ23: 否 | AK23: 卡车 | AL23: SHANGHAI FLYING FISH SUPPLY CHAIN TECHNOLOGY CO.,L | AM23: AOSOM NJ-1 | AP23: 2026-02-27 23:59:59 | AQ23: 2026-02-25 12:00:00 | AS23: 2026-02-25 12:00:00 | AT23: 2026-02-25 12:00:00 | AU23: Drop off | AW23: 2026-02-26 12:00:00 | AX23: 2026-02-27 00:00:00 | AZ23: 2026-03-06 23:59:59 | BA23: 2026-03-02 00:00:00 | BK23: FOB | BL23: 423 | BM23: 66.27 | BN23: 9439.7 | BO23: 24199.91 | BP23: 24199.91 | BQ23: 24199.91 | BR23: 0 | BS23: 美元 | BT23: 2529 | BV23: SYNERGY BUSAN | BW23: 552N | BX23: 已申报 | BY23: 2025-12-25 21:01:39 | CD23: 2026-01-03 20:12:55 | CG23: 262777253 | CH23: MAEU | CI23: MAEU262777253 | CJ23: MAEU262777253 | CP23: 2026-01-03 00:00:00 | CT23: B2B：需换单
A24: 否 | B24: AOSOM LLC | C24: 25DSA5694 | D24: 25DSA5694 | E24: 25DSA5694 | F24: 已出运 | G24: 未清关 | H24: 已到中转港 | I24: MSBU5432170 | J24: 1811F026PE20135E1 | K24: MSC | L24: 40HQ | N24: 否 | O24: 0 | P24: 福州 | Q24: 纽约 | R24: 宁波天图翼联物流科技有限公司 | S24: New Jersey Warehouse Group | T24: 2026-03-06 00:00:00 | U24: 2026-03-06 00:00:00 | V24: 2026-01-01 00:00:00 | W24: 2026-02-04 23:59:59 | Y24: SODARISE INC | Z24: 否 | AA24: 全部生成 | AB24: 2026-02-13 20:00:31 | AD24: 釜山 | AE24: 2026-01-23 07:00:00 | AJ24: 否 | AK24: 卡车 | AL24: JK EXPRESS USA INC | AM24: AOSOM NJ-1 | AP24: 2026-03-11 23:59:59 | AQ24: 2026-03-05 12:00:00 | AS24: 2026-03-05 12:00:00 | AT24: 2026-03-05 12:00:00 | AU24: Drop off | AW24: 2026-03-06 12:00:00 | AX24: 2026-03-08 00:00:00 | AZ24: 2026-03-30 23:59:59 | BA24: 2026-03-09 00:00:00 | BK24: FOB | BL24: 730 | BM24: 69.65 | BN24: 12566 | BO24: 25687.1 | BP24: 25687.1 | BQ24: 25687.1 | BR24: 0 | BS24: 美元 | BT24: 3006.1 | BV24: MSC MAKALU III | BW24: HD601A | BX24: 已申报 | BY24: 2025-12-29 21:01:36 | CD24: 2026-01-03 02:22:33 | CG24: MEDUF3542794 | CH24: MEDU | CI24: MEDUF3542794 | CJ24: MEDUF3542794 | CP24: 2026-01-02 00:00:00 | CT24: B2B：需换单
A25: 否 | B25: AOSOM LLC | C25: 25DSA5695 | D25: 25DSA5695 | E25: 25DSA5695 | F25: 已出运 | G25: 未清关 | H25: 已到中转港 | I25: TRHU8205011 | J25: 1811F026PE20238E1 | K25: MSC | L25: 40HQ | N25: 否 | O25: 0 | P25: 福州 | Q25: 纽约 | R25: 宁波天图翼联物流科技有限公司 | S25: New Jersey Warehouse Group | T25: 2026-03-08 00:00:00 | U25: 2026-03-08 00:00:00 | V25: 2026-01-08 00:00:00 | Y25: Sen Mart International Inc. | Z25: 否 | AA25: 全部传递 | AD25: 釜山 | AE25: 2026-01-31 08:28:08 | AJ25: 否 | AK25: 卡车 | AL25: JK EXPRESS USA INC | AM25: AOSOM NJ-1 | AP25: 2026-03-12 23:59:59 | AQ25: 2026-03-11 12:00:00 | AS25: 2026-03-11 12:00:00 | AT25: 2026-03-11 12:00:00 | AU25: Drop off | AW25: 2026-03-12 12:00:00 | AX25: 2026-03-13 00:00:00 | AZ25: 2026-04-03 23:59:59 | BA25: 2026-03-16 00:00:00 | BK25: FOB | BL25: 691 | BM25: 65.67 | BN25: 18731 | BO25: 25683.73 | BP25: 25683.73 | BQ25: 25683.73 | BR25: 0 | BS25: 美元 | BT25: 2934.1 | BV25: MSC MANU | BW25: HD602A | BX25: 已申报 | BY25: 2026-01-05 21:01:56 | CD25: 2026-01-09 20:22:49 | CG25: MEDUF3544246 | CH25: MEDU | CI25: MEDUF3544246 | CJ25: MEDUF3544246 | CP25: 2026-02-09 00:00:00 | CT25: B2B：需换单
A26: 否 | B26: AOSOM LLC | C26: 25DSA5696 | D26: 25DSA5696 | E26: 25DSA5696 | F26: 已出运 | G26: 未清关 | H26: 已到中转港 | I26: MSDU7885255 | J26: 1811F026PE20140E1 | K26: MSC | L26: 40HQ | N26: 否 | O26: 0 | P26: 福州 | Q26: 纽约 | R26: 宁波天图翼联物流科技有限公司 | S26: New Jersey Warehouse Group | T26: 2026-03-15 00:00:00 | U26: 2026-03-15 00:00:00 | V26: 2026-01-20 00:00:00 | Y26: SODARISE INC | Z26: 否 | AA26: 全部传递 | AD26: 釜山 | AE26: 2026-02-07 08:01:51 | AJ26: 否 | AK26: 卡车 | AL26: JK EXPRESS USA INC | AM26: AOSOM NJ-1 | AP26: 2026-03-19 23:59:59 | AQ26: 2026-03-18 12:00:00 | AS26: 2026-03-18 12:00:00 | AT26: 2026-03-18 12:00:00 | AU26: Drop off | AW26: 2026-03-19 12:00:00 | AX26: 2026-03-18 00:00:00 | AZ26: 2026-04-10 23:59:59 | BA26: 2026-03-19 00:00:00 | BK26: FOB | BL26: 795 | BM26: 69.3 | BN26: 18845.55 | BO26: 25829.4 | BP26: 25829.4 | BQ26: 25829.4 | BR26: 0 | BS26: 美元 | BT26: 2934.1 | BV26: XIN BIN ZHOU | BW26: HD603A | BX26: 已申报 | BY26: 2026-01-12 21:02:03 | CD26: 2026-01-20 19:52:24 | CG26: MEDUF3542885 | CH26: MEDU | CI26: MEDUF3542885 | CJ26: MEDUF3542885 | CP26: 2026-01-15 00:00:00 | CS26: Y | CT26: B2B：需换单
A27: 否 | B27: AOSOM LLC | C27: 25DSA5697 | D27: 25DSA5697 | E27: 25DSA5697 | F27: 已出运 | G27: 未清关 | H27: 已到中转港 | I27: MSMU4283923 | J27: 1811F026PE21064E1 | K27: MSC | L27: 40HQ | N27: 否 | O27: 0 | P27: 福州 | Q27: 纽约 | R27: 宁波天图翼联物流科技有限公司 | S27: New Jersey Warehouse Group | T27: 2026-03-15 00:00:00 | U27: 2026-03-15 00:00:00 | V27: 2026-01-25 00:00:00 | Y27: Sen Mart International Inc. | Z27: 否 | AA27: 全部传递 | AD27: 釜山 | AE27: 2026-02-12 16:55:30 | AJ27: 否 | AK27: 卡车 | AL27: JK EXPRESS USA INC | AM27: AOSOM NJ-1 | AP27: 2026-03-19 23:59:59 | AQ27: 2026-03-18 12:00:00 | AS27: 2026-03-18 12:00:00 | AT27: 2026-03-18 12:00:00 | AU27: Drop off | AW27: 2026-03-19 12:00:00 | AX27: 2026-03-18 00:00:00 | AZ27: 2026-04-10 23:59:59 | BA27: 2026-03-19 00:00:00 | BK27: FOB | BL27: 610 | BM27: 79.11 | BN27: 16203.8 | BO27: 19546.1 | BP27: 19546.1 | BQ27: 19546.1 | BR27: 0 | BS27: 美元 | BT27: 2934.1 | BV27: MSC TIGER III | BW27: HD604A | BX27: 已申报 | BY27: 2026-01-19 21:02:11 | CD27: 2026-01-25 19:59:41 | CG27: MEDUF3557842 | CH27: MEDU | CI27: MEDUF3557842 | CJ27: MEDUF3557842 | CP27: 2026-02-15 00:00:00 | CT27: B2B：需换单
A28: 否 | B28: AOSOM LLC | C28: 25DSA5707 | D28: 25DSA5707 | E28: 25DSA5707 | F28: 已出运 | G28: 已完成 | H28: 已还箱 | I28: HASU4895030 | J28: 277629003 | K28: MAERSK | L28: 40HQ | N28: 否 | O28: 0 | P28: 宁波 | Q28: 萨凡纳 | R28: 简达物流集团股份有限公司 | S28: Atlanta warehouse group | T28: 2026-02-06 20:00:00 | U28: 2026-02-06 20:00:00 | V28: 2026-01-02 00:00:00 | W28: 2026-02-03 23:59:59 | Y28: Sen Mart International Inc. | Z28: 否 | AA28: 全部生成 | AB28: 2026-02-13 19:56:31 | AF28: 2026-02-05 11:10:00 | AG28: 2026-02-06 11:04:00 | AH28: GARDEN CITY MARINE TERMINAL | AI28: 2026-02-13 23:59:59 | AJ28: 否 | AK28: 卡车 | AL28: LFT TRANSPORTATION INC | AM28: AOSOM GA-1 | AN28: AOSOM GA-1 | AO28: 2026-02-16 06:39:21 | AP28: 2026-02-13 23:59:59 | AQ28: 2026-02-12 23:59:59 | AR28: 2026-02-11 17:53:57 | AS28: 2026-02-12 23:59:59 | AT28: 2026-02-12 23:59:59 | AU28: Drop off | AW28: 2026-02-13 23:59:59 | AX28: 2026-02-13 16:44:56 | AZ28: 2026-02-20 23:59:59 | BA28: 2026-02-14 16:44:56 | BB28: 2026-02-16 07:56:00 | BK28: FOB | BL28: 753 | BM28: 65.31 | BN28: 7160.4 | BO28: 12391.72 | BP28: 12391.72 | BQ28: 12391.72 | BR28: 0 | BS28: 美元 | BT28: 2529 | BV28: MAERSK SINGAPORE | BW28: 552E | BX28: 已申报 | BY28: 2025-12-22 21:01:59 | CD28: 2026-01-03 02:13:55 | CG28: 277629003 | CH28: MAEU | CI28: MAEU277629003 | CJ28: MAEU277629003 | CM28: WMS已完成 | CN28: 已入库 | CO28: 2026-02-16 04:26:21 | CP28: 2026-01-03 00:00:00 | CT28: B2B：需换单
